# Translations template for cinder.
# Copyright (C) 2016 ORGANIZATION
# This file is distributed under the same license as the cinder project.
# FIRST AUTHOR <EMAIL@ADDRESS>, 2016.
#
#, fuzzy
msgid ""
msgstr ""
"Project-Id-Version: cinder 8.0.0.0b4.dev42\n"
"Report-Msgid-Bugs-To: EMAIL@ADDRESS\n"
"POT-Creation-Date: 2016-03-04 06:35+0000\n"
"PO-Revision-Date: YEAR-MO-DA HO:MI+ZONE\n"
"Last-Translator: FULL NAME <EMAIL@ADDRESS>\n"
"Language-Team: LANGUAGE <LL@li.org>\n"
"MIME-Version: 1.0\n"
"Content-Type: text/plain; charset=utf-8\n"
"Content-Transfer-Encoding: 8bit\n"
"Generated-By: Babel 2.2.0\n"

#: cinder/coordination.py:95
msgid "Error starting coordination backend."
msgstr ""

#: cinder/coordination.py:152
msgid "Connection error while sending a heartbeat to coordination backend."
msgstr ""

#: cinder/coordination.py:156
msgid "Error sending a heartbeat to coordination backend."
msgstr ""

#: cinder/exception.py:111
msgid "Exception in string format operation"
msgstr ""

#: cinder/exception.py:113
#, python-format
msgid "%(name)s: %(value)s"
msgstr ""

#: cinder/quota.py:1041
#, python-format
msgid "Failed to commit reservations %s"
msgstr ""

#: cinder/quota.py:1062
#, python-format
msgid "Failed to roll back reservations %s"
msgstr ""

#: cinder/service.py:305
#, python-format
msgid ""
"Manager for service %(binary)s %(host)s is reporting problems, not "
"sending heartbeat. Service will appear \"down\"."
msgstr ""

#: cinder/service.py:332
msgid "Recovered model server connection!"
msgstr ""

#: cinder/service.py:337
msgid "model server went away"
msgstr ""

#: cinder/service.py:344
msgid "DBError encountered: "
msgstr ""

#: cinder/service.py:349
msgid "Exception encountered: "
msgstr ""

#: cinder/utils.py:486
#, python-format
msgid "Failed to write persistence file: %(path)s."
msgstr ""

#: cinder/utils.py:595
#, python-format
msgid "Volume driver %s not initialized"
msgstr ""

#: cinder/api/extensions.py:244
msgid "Exception loading extension."
msgstr ""

#: cinder/api/middleware/fault.py:47
#, python-format
msgid "Caught error: %(type)s %(error)s"
msgstr ""

#: cinder/api/openstack/wsgi.py:809
#, python-format
msgid "Exception handling resource: %s"
msgstr ""

#: cinder/api/openstack/wsgi.py:1182
msgid "Get method error."
msgstr ""

#: cinder/backup/chunkeddriver.py:577
#, python-format
msgid "Backup volume metadata failed: %s."
msgstr ""

#: cinder/backup/manager.py:123
msgid "Problem cleaning incomplete backup operations."
msgstr ""

#: cinder/backup/manager.py:141
#, python-format
msgid "Problem cleaning up backup %(bkup)s."
msgstr ""

#: cinder/backup/manager.py:147 cinder/backup/manager.py:787
#, python-format
msgid "Problem cleaning temp volumes and snapshots for backup %(bkup)s."
msgstr ""

#: cinder/backup/manager.py:206
#, python-format
msgid "Detach attachment %(attach_id)s failed."
msgstr ""

#: cinder/backup/manager.py:512
msgid "Failed to update usages deleting backup"
msgstr ""

#: cinder/backup/manager.py:762
#, python-format
msgid "Backup id %s is not invalid. Skipping reset."
msgstr ""

#: cinder/backup/manager.py:766
#, python-format
msgid ""
"Backup service %(configured_service)s does not support verify. Backup id "
"%(id)s is not verified. Skipping verify."
msgstr ""

#: cinder/backup/drivers/ceph.py:458
#, python-format
msgid ""
"Max retries reached deleting backup %(basename)s image of volume "
"%(volume)s."
msgstr ""

#: cinder/backup/drivers/ceph.py:494
#, python-format
msgid "Pipe1 failed - %s "
msgstr ""

#: cinder/backup/drivers/ceph.py:508
#, python-format
msgid "Pipe2 failed - %s "
msgstr ""

#: cinder/backup/drivers/ceph.py:969
msgid "Differential restore failed, trying full restore"
msgstr ""

#: cinder/backup/drivers/ceph.py:1159
#, python-format
msgid "Restore to volume %(volume)s finished with error - %(error)s."
msgstr ""

#: cinder/backup/drivers/swift.py:203
#, python-format
msgid "single_user auth mode enabled, but %(param)s not set"
msgstr ""

#: cinder/backup/drivers/tsm.py:252
#, python-format
msgid ""
"backup: %(vol_id)s failed to remove backup hardlink from %(vpath)s to "
"%(bpath)s.\n"
"stdout: %(out)s\n"
" stderr: %(err)s."
msgstr ""

#: cinder/backup/drivers/tsm.py:524
#, python-format
msgid ""
"delete: %(vol_id)s failed with stdout: %(out)s\n"
" stderr: %(err)s"
msgstr ""

#: cinder/brick/local_dev/lvm.py:89
msgid "Error creating Volume Group"
msgstr ""

#: cinder/brick/local_dev/lvm.py:90 cinder/brick/local_dev/lvm.py:184
#: cinder/brick/local_dev/lvm.py:558 cinder/brick/local_dev/lvm.py:589
#: cinder/brick/local_dev/lvm.py:611 cinder/brick/local_dev/lvm.py:653
#: cinder/brick/local_dev/lvm.py:742 cinder/brick/local_dev/lvm.py:780
#, python-format
msgid "Cmd     :%s"
msgstr ""

#: cinder/brick/local_dev/lvm.py:91 cinder/brick/local_dev/lvm.py:185
#: cinder/brick/local_dev/lvm.py:559 cinder/brick/local_dev/lvm.py:590
#: cinder/brick/local_dev/lvm.py:612 cinder/brick/local_dev/lvm.py:654
#: cinder/brick/local_dev/lvm.py:743 cinder/brick/local_dev/lvm.py:781
#, python-format
msgid "StdOut  :%s"
msgstr ""

#: cinder/brick/local_dev/lvm.py:92 cinder/brick/local_dev/lvm.py:186
#: cinder/brick/local_dev/lvm.py:560 cinder/brick/local_dev/lvm.py:591
#: cinder/brick/local_dev/lvm.py:613 cinder/brick/local_dev/lvm.py:655
#: cinder/brick/local_dev/lvm.py:744 cinder/brick/local_dev/lvm.py:782
#, python-format
msgid "StdErr  :%s"
msgstr ""

#: cinder/brick/local_dev/lvm.py:96
#, python-format
msgid "Unable to locate Volume Group %s"
msgstr ""

#: cinder/brick/local_dev/lvm.py:183
msgid "Error querying thin pool about data_percent"
msgstr ""

#: cinder/brick/local_dev/lvm.py:410
#, python-format
msgid "Unable to find VG: %s"
msgstr ""

#: cinder/brick/local_dev/lvm.py:497
msgid ""
"Requested to setup thin provisioning, however current LVM version does "
"not support it."
msgstr ""

#: cinder/brick/local_dev/lvm.py:557
msgid "Error creating Volume"
msgstr ""

#: cinder/brick/local_dev/lvm.py:574
#, python-format
msgid "Trying to create snapshot by non-existent LV: %s"
msgstr ""

#: cinder/brick/local_dev/lvm.py:588
#: cinder/volume/drivers/nexenta/nexentaedge/iscsi.py:205
msgid "Error creating snapshot"
msgstr ""

#: cinder/brick/local_dev/lvm.py:610
msgid "Error deactivating LV"
msgstr ""

#: cinder/brick/local_dev/lvm.py:652
msgid "Error activating LV"
msgstr ""

#: cinder/brick/local_dev/lvm.py:741
msgid "Error extending Volume"
msgstr ""

#: cinder/brick/local_dev/lvm.py:779
msgid "Error renaming logical volume"
msgstr ""

#: cinder/cmd/all.py:77
msgid "Failed to load osapi_volume"
msgstr ""

#: cinder/cmd/all.py:83
#, python-format
msgid "Failed to load %s"
msgstr ""

#: cinder/cmd/all.py:105
msgid "Failed to load conder-volume"
msgstr ""

#: cinder/cmd/volume_usage_audit.py:120
#, python-format
msgid "Exists volume notification failed: %s"
msgstr ""

#: cinder/cmd/volume_usage_audit.py:146
#, python-format
msgid "Create volume notification failed: %s"
msgstr ""

#: cinder/cmd/volume_usage_audit.py:172
#, python-format
msgid "Delete volume notification failed: %s"
msgstr ""

#: cinder/cmd/volume_usage_audit.py:190
#, python-format
msgid "Exists snapshot notification failed: %s"
msgstr ""

#: cinder/cmd/volume_usage_audit.py:216
#, python-format
msgid "Create snapshot notification failed: %s"
msgstr ""

#: cinder/cmd/volume_usage_audit.py:242
#, python-format
msgid "Delete snapshot notification failed: %s"
msgstr ""

#: cinder/consistencygroup/api.py:151
#, python-format
msgid "Error occurred when creating consistency group %s."
msgstr ""

#: cinder/consistencygroup/api.py:183
#, python-format
msgid ""
"CG snapshot %(cgsnap)s not found when creating consistency group %(cg)s "
"from source."
msgstr ""

#: cinder/consistencygroup/api.py:197
#, python-format
msgid ""
"Source CG %(source_cg)s not found when creating consistency group %(cg)s "
"from source."
msgstr ""

#: cinder/consistencygroup/api.py:228
#, python-format
msgid ""
"Error occurred when creating consistency group %(cg)s from cgsnapshot "
"%(cgsnap)s."
msgstr ""

#: cinder/consistencygroup/api.py:281
#, python-format
msgid ""
"Error occurred when creating volume entry from snapshot in the process of"
" creating consistency group %(group)s from cgsnapshot %(cgsnap)s."
msgstr ""

#: cinder/consistencygroup/api.py:292
#, python-format
msgid ""
"Error occurred when creating consistency group %(group)s from cgsnapshot "
"%(cgsnap)s."
msgstr ""

#: cinder/consistencygroup/api.py:342
#, python-format
msgid ""
"Error occurred when creating cloned volume in the process of creating "
"consistency group %(group)s from source CG %(source_cg)s."
msgstr ""

#: cinder/consistencygroup/api.py:353
#, python-format
msgid ""
"Error occurred when creating consistency group %(group)s from source CG "
"%(source_cg)s."
msgstr ""

#: cinder/consistencygroup/api.py:411
#, python-format
msgid "Error occurred when building request spec list for consistency group %s."
msgstr ""

#: cinder/consistencygroup/api.py:437
#, python-format
msgid "Failed to update quota for consistency group %s."
msgstr ""

#: cinder/consistencygroup/api.py:756
#, python-format
msgid "Error occurred when creating cgsnapshot %s."
msgstr ""

#: cinder/db/sqlalchemy/api.py:2872
#, python-format
msgid "VolumeType %s deletion failed, VolumeType in use."
msgstr ""

#: cinder/db/sqlalchemy/api.py:3892
#, python-format
msgid "Volume in unexpected state %s, expected awaiting-transfer"
msgstr ""

#: cinder/db/sqlalchemy/api.py:4265
#, python-format
msgid "DBError detected when purging from table=%(table)s"
msgstr ""

#: cinder/image/glance.py:181
#, python-format
msgid "Error contacting glance server '%(netloc)s' for '%(method)s', %(extra)s."
msgstr ""

#: cinder/keymgr/barbican.py:115
msgid "Error creating Barbican client."
msgstr ""

#: cinder/keymgr/barbican.py:152
msgid "Error creating key."
msgstr ""

#: cinder/keymgr/barbican.py:208
msgid "Error storing key."
msgstr ""

#: cinder/keymgr/barbican.py:236
msgid "Error copying key."
msgstr ""

#: cinder/keymgr/barbican.py:273
msgid "Error getting secret data."
msgstr ""

#: cinder/keymgr/barbican.py:292
msgid "Error getting secret metadata."
msgstr ""

#: cinder/keymgr/barbican.py:321
msgid "Error getting key."
msgstr ""

#: cinder/keymgr/barbican.py:338
msgid "Error deleting key."
msgstr ""

#: cinder/scheduler/filter_scheduler.py:214
#, python-format
msgid ""
"Error scheduling %(volume_id)s from last vol-service: %(last_host)s : "
"%(exc)s"
msgstr ""

#: cinder/scheduler/manager.py:109
#, python-format
msgid "Could not find a host for consistency group %(group_id)s."
msgstr ""

#: cinder/scheduler/manager.py:116
#, python-format
msgid "Failed to create consistency group %(group_id)s."
msgstr ""

#: cinder/scheduler/manager.py:296
#, python-format
msgid "Failed to schedule_%(method)s: %(ex)s"
msgstr ""

#: cinder/scheduler/scheduler_options.py:69
#, python-format
msgid "Could not stat scheduler options file %(filename)s."
msgstr ""

#: cinder/scheduler/scheduler_options.py:79
msgid "Could not decode scheduler options."
msgstr ""

#: cinder/scheduler/filters/capacity_filter.py:46
msgid "Free capacity not set: volume node info collection broken."
msgstr ""

#: cinder/scheduler/flows/create_volume.py:98
#, python-format
msgid "Failed to run task %(name)s: %(cause)s"
msgstr ""

#: cinder/scheduler/flows/create_volume.py:115
#, python-format
msgid "Failed notifying on %(topic)s payload %(payload)s"
msgstr ""

#: cinder/transfer/api.py:72
msgid "Volume in unexpected state"
msgstr ""

#: cinder/transfer/api.py:137
#, python-format
msgid "Failed to create transfer record for %s"
msgstr ""

#: cinder/transfer/api.py:220
#, python-format
msgid "Failed to update quota donating volume transfer id %s"
msgstr ""

#: cinder/volume/api.py:357
msgid "Failed to update quota while deleting volume."
msgstr ""

#: cinder/volume/api.py:1225
#, python-format
msgid ""
"Quota exceeded for %(s_pid)s, tried to extend volume by %(s_size)sG, "
"(%(d_consumed)dG of %(d_quota)dG already consumed)."
msgstr ""

#: cinder/volume/api.py:1531 cinder/volume/api.py:1576
#, python-format
msgid "Unable to find service: %(service)s for given host: %(host)s."
msgstr ""

#: cinder/volume/driver.py:368 cinder/volume/drivers/hitachi/hnas_nfs.py:379
#: cinder/volume/drivers/netapp/dataontap/nfs_base.py:279
#, python-format
msgid "Recovering from a failed execute.  Try number %s"
msgstr ""

#: cinder/volume/driver.py:402
#, python-format
msgid "Error detaching volume %(volume)s, due to remove export failure."
msgstr ""

#: cinder/volume/driver.py:424
msgid "Detaching snapshot from a remote node is not supported."
msgstr ""

#: cinder/volume/driver.py:445
#, python-format
msgid "Error detaching snapshot %(snapshot)s, due to remove export failure."
msgstr ""

#: cinder/volume/driver.py:882
#, python-format
msgid ""
"Failed updating model of volume %(volume_id)s with driver provided model "
"%(model)s"
msgstr ""

#: cinder/volume/driver.py:921
#: cinder/volume/drivers/hpe/hpe_3par_common.py:2313
#, python-format
msgid "Error detaching volume %s"
msgstr ""

#: cinder/volume/driver.py:937
msgid "Attaching snapshot from a remote node is not supported."
msgstr ""

#: cinder/volume/driver.py:958
#, python-format
msgid ""
"Failed updating model of snapshot %(snapshot_id)s with driver provided "
"model %(model)s."
msgstr ""

#: cinder/volume/driver.py:1007
#, python-format
msgid "Could not validate device %s"
msgstr ""

#: cinder/volume/driver.py:2343 cinder/volume/targets/iscsi.py:167
#, python-format
msgid "ISCSI discovery attempt failed for:%s"
msgstr ""

#: cinder/volume/driver.py:2532
#, python-format
msgid "The volume driver requires %(data)s in the connector."
msgstr ""

#: cinder/volume/driver.py:2804
#, python-format
msgid ""
"FibreChannelDriver validate_connector failed. No '%(setting)s'. Make sure"
" HBA state is Online."
msgstr ""

#: cinder/volume/manager.py:283
#, python-format
msgid "Invalid JSON: %s"
msgstr ""

#: cinder/volume/manager.py:320
msgid "Fetch volume pool name failed."
msgstr ""

#: cinder/volume/manager.py:416
msgid "Failed to initialize driver."
msgstr ""

#: cinder/volume/manager.py:444
msgid "Failed to re-export volume, setting to ERROR."
msgstr ""

#: cinder/volume/manager.py:474
msgid "Error during re-export on driver init."
msgstr ""

#: cinder/volume/manager.py:734
msgid "Unable to delete busy volume."
msgstr ""

#: cinder/volume/manager.py:763
msgid "Failed to update usages deleting volume."
msgstr ""

#: cinder/volume/manager.py:805
msgid ""
"Unable to delete the destination volume during volume migration, (NOTE: "
"database record needs to be deleted)."
msgstr ""

#: cinder/volume/manager.py:850
#, python-format
msgid ""
"Failed updating snapshot metadata using the provided volumes "
"%(volume_id)s metadata"
msgstr ""

#: cinder/volume/manager.py:893
msgid "Delete snapshot failed, due to snapshot busy."
msgstr ""

#: cinder/volume/manager.py:921
msgid "Update snapshot usages failed."
msgstr ""

#: cinder/volume/manager.py:1110
msgid "Detach volume failed, due to uninitialized driver."
msgstr ""

#: cinder/volume/manager.py:1114
msgid "Detach volume failed, due to remove-export failure."
msgstr ""

#: cinder/volume/manager.py:1182
#, python-format
msgid ""
"Create clone_image_volume: %(volume_id)sfor image %(image_id)s, failed "
"(Exception: %(except)s)"
msgstr ""

#: cinder/volume/manager.py:1207
#, python-format
msgid "Failed to clone volume %(volume_id)s for image %(image_id)s."
msgstr ""

#: cinder/volume/manager.py:1214
#, python-format
msgid "Could not delete the image volume %(id)s."
msgstr ""

#: cinder/volume/manager.py:1244
#, python-format
msgid "Failed to register image volume location %(uri)s."
msgstr ""

#: cinder/volume/manager.py:1254
#, python-format
msgid "Could not delete failed image volume %(id)s."
msgstr ""

#: cinder/volume/manager.py:1299
#, python-format
msgid "Upload volume to image encountered an error (image-id: %(image_id)s)."
msgstr ""

#: cinder/volume/manager.py:1351
#, python-format
msgid ""
"Failed to get driver initiator data for initiator %(initiator)s and "
"namespace %(namespace)s"
msgstr ""

#: cinder/volume/manager.py:1368
#, python-format
msgid ""
"Failed to update initiator data for initiator %(initiator)s and backend "
"%(backend)s"
msgstr ""

#: cinder/volume/manager.py:1442
msgid "Model update failed."
msgstr ""

#: cinder/volume/manager.py:1572
msgid "Update volume model for transfer operation failed."
msgstr ""

#: cinder/volume/manager.py:1620
#, python-format
msgid "Failed to attach volume %(vol)s."
msgstr ""

#: cinder/volume/manager.py:1646
#, python-format
msgid "Unable to terminate volume connection: %(err)s."
msgstr ""

#: cinder/volume/manager.py:1667
msgid "Failed to attach source volume for copy."
msgstr ""

#: cinder/volume/manager.py:1690
#, python-format
msgid "Failed to copy volume %(src)s to %(dest)s."
msgstr ""

#: cinder/volume/manager.py:1775
#, python-format
msgid "Failed to copy volume %(vol1)s to %(vol2)s"
msgstr ""

#: cinder/volume/manager.py:1866
#, python-format
msgid "Detach migration source volume failed:  %(err)s"
msgstr ""

#: cinder/volume/manager.py:1901
#, python-format
msgid "Failed to request async delete of migration source vol %(vol)s: %(err)s"
msgstr ""

#: cinder/volume/manager.py:2115
msgid "Extend volume failed."
msgstr ""

#: cinder/volume/manager.py:2257
#, python-format
msgid ""
"Volume %s: driver error when trying to retype, falling back to generic "
"mechanism."
msgstr ""

#: cinder/volume/manager.py:2362
msgid "Promote volume replica failed."
msgstr ""

#: cinder/volume/manager.py:2395
msgid "Sync volume replica failed."
msgstr ""

#: cinder/volume/manager.py:2431
msgid "Get replication status for volume failed."
msgstr ""

#: cinder/volume/manager.py:2466
#, python-format
msgid "Consistency group %s: create failed"
msgstr ""

#: cinder/volume/manager.py:2501
#, python-format
msgid "Create consistency group from snapshot-%(snap)s failed: SnapshotNotFound."
msgstr ""

#: cinder/volume/manager.py:2529
#, python-format
msgid ""
"Create consistency group from source cg-%(cg)s failed: "
"ConsistencyGroupNotFound."
msgstr ""

#: cinder/volume/manager.py:2588
#, python-format
msgid "Create consistency group from source %(source)s failed."
msgstr ""

#: cinder/volume/manager.py:2632
#, python-format
msgid "Source snapshot cannot be found for target volume %(volume_id)s."
msgstr ""

#: cinder/volume/manager.py:2655
#, python-format
msgid "Source volumes cannot be found for target volume %(volume_id)s."
msgstr ""

#: cinder/volume/manager.py:2676
#, python-format
msgid "Source snapshot %(snapshot_id)s cannot be found."
msgstr ""

#: cinder/volume/manager.py:2685
#, python-format
msgid "The source volume %(volume_id)s cannot be found."
msgstr ""

#: cinder/volume/manager.py:2695
#, python-format
msgid ""
"Failed to update %(volume_id)s metadata using the provided snapshot "
"%(snapshot_id)s metadata."
msgstr ""

#: cinder/volume/manager.py:2803 cinder/volume/manager.py:2822
msgid "Delete consistency group failed to update usages."
msgstr ""

#: cinder/volume/manager.py:2873
#, python-format
msgid ""
"Update consistency group failed to add volume-%(volume_id)s: "
"VolumeNotFound."
msgstr ""

#: cinder/volume/manager.py:2902
#, python-format
msgid ""
"Update consistency group failed to remove volume-%(volume_id)s: "
"VolumeNotFound."
msgstr ""

#: cinder/volume/manager.py:2952
#, python-format
msgid ""
"Error occurred in the volume driver when updating consistency group "
"%(group_id)s."
msgstr ""

#: cinder/volume/manager.py:2965
#, python-format
msgid "Error occurred when updating consistency group %(group_id)s."
msgstr ""

#: cinder/volume/manager.py:3074
#, python-format
msgid ""
"Failed updating %(snapshot_id)s metadata using the provided volumes "
"%(volume_id)s metadata"
msgstr ""

#: cinder/volume/manager.py:3188
msgid "Failed to update usages deleting snapshot"
msgstr ""

#: cinder/volume/manager.py:3294
msgid "Failed to perform replication failover"
msgstr ""

#: cinder/volume/manager.py:3299
msgid "Invalid replication target specified for failover"
msgstr ""

#: cinder/volume/manager.py:3308
msgid "Driver reported error during replication failover."
msgstr ""

#: cinder/volume/manager.py:3315
#, python-format
msgid ""
"Error encountered during failover on host: %(host)s invalid target ID "
"%(backend_id)"
msgstr ""

#: cinder/volume/manager.py:3404
msgid ""
"Error encountered on Cinder backend during thaw operation, service will "
"remain frozen."
msgstr ""

#: cinder/volume/manager.py:3430
#, python-format
msgid "Failed to create manage_existing flow: %(object_type)s %(object_id)s."
msgstr ""

#: cinder/volume/qos_specs.py:87 cinder/volume/qos_specs.py:108
#: cinder/volume/qos_specs.py:158 cinder/volume/qos_specs.py:200
#: cinder/volume/qos_specs.py:214 cinder/volume/qos_specs.py:228
#: cinder/volume/volume_types.py:55 cinder/volume/volume_types.py:81
msgid "DB error:"
msgstr ""

#: cinder/volume/throttling.py:72
#, python-format
msgid "Failed to create blkio cgroup '%(name)s'."
msgstr ""

#: cinder/volume/throttling.py:80
#, python-format
msgid "Failed to get device number for throttling: %(error)s"
msgstr ""

#: cinder/volume/utils.py:375
#, python-format
msgid "Failed to open volume from %(path)s."
msgstr ""

#: cinder/volume/volume_types.py:145
msgid "Default volume type is not found. Please check default_volume_type config:"
msgstr ""

#: cinder/volume/drivers/datera.py:118
msgid ""
"Logging into the Datera cluster failed. Please check your username and "
"password set in the cinder.conf and start the cinder-volume service "
"again."
msgstr ""

#: cinder/volume/drivers/datera.py:156
msgid ""
"Creation request failed. Please verify the extra-specs set for your "
"volume types are entered correctly."
msgstr ""

#: cinder/volume/drivers/datera.py:367
msgid "Failed to get updated stats from Datera cluster."
msgstr ""

#: cinder/volume/drivers/datera.py:377
msgid "Failed to get updated stats from Datera Cluster."
msgstr ""

#: cinder/volume/drivers/drbdmanagedrv.py:867
msgid "DRBDmanage: too many assignments returned."
msgstr ""

#: cinder/volume/drivers/eqlx.py:227
#, python-format
msgid "%s"
msgstr ""

#: cinder/volume/drivers/eqlx.py:265
msgid "Error running command."
msgstr ""

#: cinder/volume/drivers/eqlx.py:275
#, python-format
msgid "Error running SSH command: \"%s\"."
msgstr ""

#: cinder/volume/drivers/eqlx.py:412
msgid "Failed to setup the Dell EqualLogic driver."
msgstr ""

#: cinder/volume/drivers/eqlx.py:429
#, python-format
msgid "Failed to create volume \"%s\"."
msgstr ""

#: cinder/volume/drivers/eqlx.py:439
#, python-format
msgid "Failed to add multihost-access for volume \"%s\"."
msgstr ""

#: cinder/volume/drivers/eqlx.py:454
#, python-format
msgid "Failed to delete volume \"%s\"."
msgstr ""

#: cinder/volume/drivers/eqlx.py:470
#, python-format
msgid "Failed to create snapshot of volume \"%s\"."
msgstr ""

#: cinder/volume/drivers/eqlx.py:484
#, python-format
msgid "Failed to create volume from snapshot \"%s\"."
msgstr ""

#: cinder/volume/drivers/eqlx.py:497
#, python-format
msgid "Failed to create clone of volume \"%s\"."
msgstr ""

#: cinder/volume/drivers/eqlx.py:507
#, python-format
msgid "Failed to delete snapshot %(snap)s of volume %(vol)s."
msgstr ""

#: cinder/volume/drivers/eqlx.py:528
#, python-format
msgid "Failed to initialize connection to volume \"%s\"."
msgstr ""

#: cinder/volume/drivers/eqlx.py:543
#, python-format
msgid "Failed to terminate connection to volume \"%s\"."
msgstr ""

#: cinder/volume/drivers/eqlx.py:569
#, python-format
msgid "Failed to ensure export of volume \"%s\"."
msgstr ""

#: cinder/volume/drivers/eqlx.py:588
#, python-format
msgid ""
"Failed to extend_volume %(name)s from %(current_size)sGB to "
"%(new_size)sGB."
msgstr ""

#: cinder/volume/drivers/glusterfs.py:124
#, python-format
msgid "Failed to umount %(share)s, reason=%(stderr)s"
msgstr ""

#: cinder/volume/drivers/glusterfs.py:372 cinder/volume/drivers/remotefs.py:270
#, python-format
msgid "Exception during mounting %s"
msgstr ""

#: cinder/volume/drivers/glusterfs.py:431
#, python-format
msgid "Mount failure for %(share)s."
msgstr ""

#: cinder/volume/drivers/glusterfs.py:458
#, python-format
msgid ""
"No snapshots found in database, but %(path)s has backing file "
"%(backing_file)s!"
msgstr ""

#: cinder/volume/drivers/hgst.py:109
#, python-format
msgid ""
"CLI fail: '%(cmd)s' = %(code)s\n"
"out: %(stdout)s\n"
"err: %(stderr)s"
msgstr ""

#: cinder/volume/drivers/hgst.py:253
msgid "VGC-CLUSTER command blocked and cancelled."
msgstr ""

#: cinder/volume/drivers/lvm.py:372 cinder/volume/drivers/nfs.py:408
#: cinder/volume/drivers/dell/dell_storagecenter_common.py:611
#: cinder/volume/drivers/ibm/storwize_svc/storwize_svc_common.py:2717
#, python-format
msgid "Unable to rename the logical volume for volume: %s"
msgstr ""

#: cinder/volume/drivers/lvm.py:417
#, python-format
msgid "Unable to delete due to existing snapshot for volume: %s"
msgstr ""

#: cinder/volume/drivers/lvm.py:691
#, python-format
msgid "Destination Volume Group %s does not exist"
msgstr ""

#: cinder/volume/drivers/lvm.py:723
#, python-format
msgid "Volume migration failed due to exception: %(reason)s."
msgstr ""

#: cinder/volume/drivers/nfs.py:155 cinder/volume/drivers/nexenta/nfs.py:695
#, python-format
msgid "Mount failure for %(share)s after %(count)d attempts."
msgstr ""

#: cinder/volume/drivers/nimble.py:182
msgid ""
"Failed to create SOAP client.Check san_ip, username, password and make "
"sure the array version is compatible"
msgstr ""

#: cinder/volume/drivers/nimble.py:539
#, python-format
msgid "Re-throwing Exception %s"
msgstr ""

#: cinder/volume/drivers/pure.py:417
msgid "Unable to disconnect host from volume, could not determine Purity host"
msgstr ""

#: cinder/volume/drivers/pure.py:440
#, python-format
msgid "Disconnection failed with message: %(msg)s."
msgstr ""

#: cinder/volume/drivers/pure.py:1087
#, python-format
msgid "Disable replication on volume failed with message: %s"
msgstr ""

#: cinder/volume/drivers/pure.py:1408
#, python-format
msgid "Error finding replicated pg snapshot on %(secondary)s."
msgstr ""

#: cinder/volume/drivers/pure.py:1555
#, python-format
msgid ""
"Purity host %(host_name)s is not managed by Cinder and can't have CHAP "
"credentials modified. Remove IQN %(iqn)s from the host to resolve this "
"issue."
msgstr ""

#: cinder/volume/drivers/pure.py:1565
#, python-format
msgid ""
"Purity host %(host_name)s is managed by Cinder but CHAP credentials could"
" not be retrieved from the Cinder database."
msgstr ""

#: cinder/volume/drivers/rbd.py:224
#, python-format
msgid "error opening rbd image %s"
msgstr ""

#: cinder/volume/drivers/rbd.py:414
msgid "error refreshing volume stats"
msgstr ""

#: cinder/volume/drivers/rbd.py:1080
#, python-format
msgid "Unable to rename the logical volume for volume %s."
msgstr ""

#: cinder/volume/drivers/remotefs.py:482
#, python-format
msgid "Share %s ignored due to invalid format. Must be of form address:/export."
msgstr ""

#: cinder/volume/drivers/remotefs.py:616
#, python-format
msgid "Failed to created Cinder secure environment indicator file: %s"
msgstr ""

#: cinder/volume/drivers/remotefs.py:1278
msgid "Call to Nova to create snapshot failed"
msgstr ""

#: cinder/volume/drivers/remotefs.py:1370
msgid "Call to Nova delete snapshot failed"
msgstr ""

#: cinder/volume/drivers/sheepdog.py:91
#, python-format
msgid "Sheepdog is not installed. OSError: command is %s."
msgstr ""

#: cinder/volume/drivers/sheepdog.py:94
#, python-format
msgid "OSError: command is %s."
msgstr ""

#: cinder/volume/drivers/sheepdog.py:127
#, python-format
msgid "Qemu-img is not installed. OSError: command is %(cmd)s."
msgstr ""

#: cinder/volume/drivers/sheepdog.py:130
#, python-format
msgid "OSError: command is %(cmd)s."
msgstr ""

#: cinder/volume/drivers/sheepdog.py:145
#, python-format
msgid "Failed to check cluster status.(command: %s)"
msgstr ""

#: cinder/volume/drivers/sheepdog.py:169
#, python-format
msgid "Volume already exists. %s"
msgstr ""

#: cinder/volume/drivers/sheepdog.py:171
#, python-format
msgid "Failed to create volume. %s"
msgstr ""

#: cinder/volume/drivers/sheepdog.py:193
#, python-format
msgid "Failed to delete volume. %s"
msgstr ""

#: cinder/volume/drivers/sheepdog.py:204
#, python-format
msgid "Volume \"%s\" not found. Please check the results of \"dog vdi list\"."
msgstr ""

#: cinder/volume/drivers/sheepdog.py:210
#, python-format
msgid "Snapshot \"%s\" already exists."
msgstr ""

#: cinder/volume/drivers/sheepdog.py:212
#, python-format
msgid "Failed to create snapshot. (command: %s)"
msgstr ""

#: cinder/volume/drivers/sheepdog.py:239
#, python-format
msgid "Failed to delete snapshot. (command: %s)"
msgstr ""

#: cinder/volume/drivers/sheepdog.py:254
#, python-format
msgid "Failed to connect to sheep daemon. addr: %(addr)s, port: %(port)s"
msgstr ""

#: cinder/volume/drivers/sheepdog.py:258
#, python-format
msgid ""
"Clone volume \"%s\" already exists. Please check the results of \"dog vdi"
" list\"."
msgstr ""

#: cinder/volume/drivers/sheepdog.py:262
#, python-format
msgid "Src Volume \"%s\" not found. Please check the results of \"dog vdi list\"."
msgstr ""

#: cinder/volume/drivers/sheepdog.py:266
#, python-format
msgid "Snapshot \"%s\" not found. Please check the results of \"dog vdi list\"."
msgstr ""

#: cinder/volume/drivers/sheepdog.py:270
#, python-format
msgid "Volume size \"%sG\" is too large."
msgstr ""

#: cinder/volume/drivers/sheepdog.py:272
#, python-format
msgid "Failed to clone volume.(command: %s)"
msgstr ""

#: cinder/volume/drivers/sheepdog.py:283
#, python-format
msgid "Failed to resize vdi. vdi not found. %s"
msgstr ""

#: cinder/volume/drivers/sheepdog.py:286
#, python-format
msgid ""
"Failed to resize vdi. Shrinking vdi not supported. vdi: %(vdiname)s new "
"size: %(size)s"
msgstr ""

#: cinder/volume/drivers/sheepdog.py:291
#, python-format
msgid ""
"Failed to resize vdi. Too large volume size. vdi: %(vdiname)s new size: "
"%(size)s"
msgstr ""

#: cinder/volume/drivers/sheepdog.py:296
#, python-format
msgid "Failed to resize vdi. vdi: %(vdiname)s new size: %(size)s"
msgstr ""

#: cinder/volume/drivers/sheepdog.py:305
#, python-format
msgid "Failed to get volume status. %s"
msgstr ""

#: cinder/volume/drivers/sheepdog.py:491
#, python-format
msgid "Failed to create cloned volume %s."
msgstr ""

#: cinder/volume/drivers/solidfire.py:432
#, python-format
msgid "Failed to retrieve volume SolidFire-ID: %s in get_by_account!"
msgstr ""

#: cinder/volume/drivers/solidfire.py:632
#, python-format
msgid "Volume %s, not found on SF Cluster."
msgstr ""

#: cinder/volume/drivers/solidfire.py:635
#, python-format
msgid "Found %(count)s volumes mapped to id: %(uuid)s."
msgstr ""

#: cinder/volume/drivers/solidfire.py:717
#, python-format
msgid "Failed image conversion during cache creation: %s"
msgstr ""

#: cinder/volume/drivers/solidfire.py:1115
#, python-format
msgid ""
"Account for Volume ID %s was not found on the SolidFire Cluster while "
"attempting delete_volume operation!"
msgstr ""

#: cinder/volume/drivers/solidfire.py:1118
msgid "This usually means the volume was never successfully created."
msgstr ""

#: cinder/volume/drivers/solidfire.py:1135
#, python-format
msgid ""
"Volume ID %s was not found on the SolidFire Cluster while attempting "
"delete_volume operation!"
msgstr ""

#: cinder/volume/drivers/solidfire.py:1165
#, python-format
msgid ""
"Account for Volume ID %s was not found on the SolidFire Cluster while "
"attempting create_snapshot operation!"
msgstr ""

#: cinder/volume/drivers/solidfire.py:1377
#, python-format
msgid ""
"Volume ID %s was not found on the SolidFire Cluster while attempting "
"extend_volume operation!"
msgstr ""

#: cinder/volume/drivers/solidfire.py:1444
#, python-format
msgid ""
"Volume ID %s was not found on the SolidFire Cluster while attempting "
"attach_volume operation!"
msgstr ""

#: cinder/volume/drivers/solidfire.py:1470
#, python-format
msgid ""
"Volume ID %s was not found on the SolidFire Cluster while attempting "
"detach_volume operation!"
msgstr ""

#: cinder/volume/drivers/solidfire.py:1492
#, python-format
msgid ""
"Volume ID %s was not found on the SolidFire Cluster while attempting "
"accept_transfer operation!"
msgstr ""

#: cinder/volume/drivers/solidfire.py:1619
#, python-format
msgid ""
"Account for Volume ID %s was not found on the SolidFire Cluster while "
"attempting unmanage operation!"
msgstr ""

#: cinder/volume/drivers/tintri.py:159
#, python-format
msgid "Configuration value %s is not set."
msgstr ""

#: cinder/volume/drivers/tintri.py:179 cinder/volume/drivers/tintri.py:353
#: cinder/volume/drivers/netapp/dataontap/block_base.py:323
#: cinder/volume/drivers/netapp/dataontap/nfs_base.py:193
#, python-format
msgid "Resizing %s failed. Cleaning volume."
msgstr ""

#: cinder/volume/drivers/tintri.py:267
#, python-format
msgid "Unexpected exception during cache cleanup of snapshot %s"
msgstr ""

#: cinder/volume/drivers/tintri.py:807
msgid "Exception during mounting."
msgstr ""

#: cinder/volume/drivers/xio.py:94
msgid "san ip must be configured!"
msgstr ""

#: cinder/volume/drivers/xio.py:98
msgid "san_login must be configured!"
msgstr ""

#: cinder/volume/drivers/xio.py:102
msgid "san_password must be configured!"
msgstr ""

#: cinder/volume/drivers/xio.py:119
#, python-format
msgid "Array query failed - No response (%d)!"
msgstr ""

#: cinder/volume/drivers/xio.py:134
msgid "Array query failed. No capabilities in response!"
msgstr ""

#: cinder/volume/drivers/xio.py:152
msgid "ISE FW version is not compatible with OpenStack!"
msgstr ""

#: cinder/volume/drivers/xio.py:159
msgid "Array query failed. No global id in XML response!"
msgstr ""

#: cinder/volume/drivers/xio.py:164
msgid "Array query failed. No controllers in response!"
msgstr ""

#: cinder/volume/drivers/xio.py:203
msgid "ISE globalid not set!"
msgstr ""

#: cinder/volume/drivers/xio.py:214
msgid "Primary IP must be set!"
msgstr ""

#: cinder/volume/drivers/xio.py:410
#, python-format
msgid "Connection to %s failed and no secondary!"
msgstr ""

#: cinder/volume/drivers/xio.py:421
#, python-format
msgid "Could not connect to %(primary)s or %(secondary)s!"
msgstr ""

#: cinder/volume/drivers/xio.py:494 cinder/volume/drivers/xio.py:532
#, python-format
msgid "Controller GET failed (%d)"
msgstr ""

#: cinder/volume/drivers/xio.py:519
msgid "Failed to get IQN!"
msgstr ""

#: cinder/volume/drivers/xio.py:559
#, python-format
msgid "Failed to get allocation information (%d)!"
msgstr ""

#: cinder/volume/drivers/xio.py:570
msgid "Failed to get LUN information!"
msgstr ""

#: cinder/volume/drivers/xio.py:628
#, python-format
msgid "Could not GET allocation information (%d)!"
msgstr ""

#: cinder/volume/drivers/xio.py:693
#, python-format
msgid "Failed to present volume %(name)s (%(status)d)!"
msgstr ""

#: cinder/volume/drivers/xio.py:719
#, python-format
msgid "Failed to get allocation information: %(host)s (%(status)d)!"
msgstr ""

#: cinder/volume/drivers/xio.py:753
#, python-format
msgid "Could not find any hosts (%s)"
msgstr ""

#: cinder/volume/drivers/xio.py:810
#, python-format
msgid "POST for host create failed (%s)!"
msgstr ""

#: cinder/volume/drivers/xio.py:837
#, python-format
msgid "Source volume %s not ready!"
msgstr ""

#: cinder/volume/drivers/xio.py:863
#, python-format
msgid "Prepare clone failed for %s."
msgstr ""

#: cinder/volume/drivers/xio.py:875
#, python-format
msgid "Clone %s not in prepared state!"
msgstr ""

#: cinder/volume/drivers/xio.py:881
#, python-format
msgid "Commit clone failed: %(name)s (%(status)d)!"
msgstr ""

#: cinder/volume/drivers/xio.py:894
#, python-format
msgid "Commit failed for %s!"
msgstr ""

#: cinder/volume/drivers/xio.py:1147
#, python-format
msgid "Failed to create volume: %(name)s (%(status)s)"
msgstr ""

#: cinder/volume/drivers/xio.py:1162
#, python-format
msgid "Failed to create volume %s."
msgstr ""

#: cinder/volume/drivers/xio.py:1221
#, python-format
msgid "Timed out deleting %s!"
msgstr ""

#: cinder/volume/drivers/xio.py:1240
#, python-format
msgid "modify volume: %s does not exist!"
msgstr ""

#: cinder/volume/drivers/xio.py:1249
#, python-format
msgid "Modify volume PUT failed: %(name)s (%(status)d)."
msgstr ""

#: cinder/volume/drivers/xio.py:1277
msgid "manage_existing: No source-name in ref!"
msgstr ""

#: cinder/volume/drivers/xio.py:1296
msgid "manage_existing_get_size: No source-name in ref!"
msgstr ""

#: cinder/volume/drivers/xio.py:1302
#, python-format
msgid "manage_existing_get_size: %s does not exist!"
msgstr ""

#: cinder/volume/drivers/xio.py:1312
#, python-format
msgid "unmanage: Volume %s does not exist!"
msgstr ""

#: cinder/volume/drivers/xio.py:1331
msgid "Host could not be found!"
msgstr ""

#: cinder/volume/drivers/xio.py:1339
#, python-format
msgid "Host PUT failed (%s)."
msgstr ""

#: cinder/volume/drivers/xio.py:1396
msgid "iscsi_ip_address must be set!"
msgstr ""

#: cinder/volume/drivers/cloudbyte/cloudbyte.py:304
#, python-format
msgid ""
"CloudByte operation [%(operation)s] failed for volume [%(vol)s]. "
"Exhausted all [%(max)s] attempts."
msgstr ""

#: cinder/volume/drivers/cloudbyte/cloudbyte.py:630
#, python-format
msgid "TSM [%s] not found in CloudByte storage."
msgstr ""

#: cinder/volume/drivers/cloudbyte/cloudbyte.py:932
#, python-format
msgid "CloudByte does not have a volume corresponding to OpenStack volume [%s]."
msgstr ""

#: cinder/volume/drivers/cloudbyte/cloudbyte.py:936
#, python-format
msgid "CloudByte volume information not available for OpenStack volume [%s]."
msgstr ""

#: cinder/volume/drivers/cloudbyte/cloudbyte.py:1124
#, python-format
msgid "CloudByte snapshot information is not available for OpenStack volume [%s]."
msgstr ""

#: cinder/volume/drivers/dell/dell_storagecenter_api.py:357
#, python-format
msgid "Error invalid json: %s"
msgstr ""

#: cinder/volume/drivers/dell/dell_storagecenter_api.py:360
#: cinder/volume/drivers/dell/dell_storagecenter_api.py:380
#, python-format
msgid "Error TypeError. %s"
msgstr ""

#: cinder/volume/drivers/dell/dell_storagecenter_api.py:362
#: cinder/volume/drivers/dell/dell_storagecenter_api.py:382
#, python-format
msgid "Error JSONDecodeError. %s"
msgstr ""

#: cinder/volume/drivers/dell/dell_storagecenter_api.py:377
#, python-format
msgid "Invalid API object: %s"
msgstr ""

#: cinder/volume/drivers/dell/dell_storagecenter_api.py:427
#, python-format
msgid "Unrecognized Login Response: %s"
msgstr ""

#: cinder/volume/drivers/dell/dell_storagecenter_api.py:453
#, python-format
msgid "Failed to find %(s)s.  Result %(r)s"
msgstr ""

#: cinder/volume/drivers/dell/dell_storagecenter_api.py:525
#, python-format
msgid "Unable to create folder path %s"
msgstr ""

#: cinder/volume/drivers/dell/dell_storagecenter_api.py:831
msgid "ScVolume returned success with empty payload.  Attempting to locate volume"
msgstr ""

#: cinder/volume/drivers/dell/dell_storagecenter_api.py:837
#, python-format
msgid "Unable to create volume on SC: %s"
msgstr ""

#: cinder/volume/drivers/dell/dell_storagecenter_api.py:1004
#, python-format
msgid "AddHba error: %(wwn)s to %(srvname)s"
msgstr ""

#: cinder/volume/drivers/dell/dell_storagecenter_api.py:1108
msgid "Error adding HBA to server"
msgstr ""

#: cinder/volume/drivers/dell/dell_storagecenter_api.py:1183
#, python-format
msgid "Error getting FaultDomainList for %s"
msgstr ""

#: cinder/volume/drivers/dell/dell_storagecenter_api.py:1204
msgid "Unable to find FC initiators"
msgstr ""

#: cinder/volume/drivers/dell/dell_storagecenter_api.py:1237
msgid "_find_mappings: volume is not active"
msgstr ""

#: cinder/volume/drivers/dell/dell_storagecenter_api.py:1256
#, python-format
msgid "Unable to find mapping profiles: %s"
msgstr ""

#: cinder/volume/drivers/dell/dell_storagecenter_api.py:1274
#, python-format
msgid "Unable to find controller port: %s"
msgstr ""

#: cinder/volume/drivers/dell/dell_storagecenter_api.py:1333
msgid "Volume appears unmapped"
msgstr ""

#: cinder/volume/drivers/dell/dell_storagecenter_api.py:1361
#, python-format
msgid "Unable to retrieve VolumeConfiguration: %s"
msgstr ""

#: cinder/volume/drivers/dell/dell_storagecenter_api.py:1409
#, python-format
msgid "Unable to find controller port iscsi configuration: %s"
msgstr ""

#: cinder/volume/drivers/dell/dell_storagecenter_api.py:1593
#, python-format
msgid "Unable to map %(vol)s to %(srv)s"
msgstr ""

#: cinder/volume/drivers/dell/dell_storagecenter_api.py:1631
#, python-format
msgid "Unable to unmap Volume %s"
msgstr ""

#: cinder/volume/drivers/dell/dell_storagecenter_api.py:1726
#, python-format
msgid "Invalid ReplayList return: %s"
msgstr ""

#: cinder/volume/drivers/dell/dell_storagecenter_api.py:1789
#, python-format
msgid "Unable to create volume %s from replay"
msgstr ""

#: cinder/volume/drivers/dell/dell_storagecenter_api.py:1817
msgid "Error: unable to snap replay"
msgstr ""

#: cinder/volume/drivers/dell/dell_storagecenter_api.py:1843
#, python-format
msgid "Error expanding volume %s."
msgstr ""

#: cinder/volume/drivers/dell/dell_storagecenter_api.py:1863
#, python-format
msgid "Error renaming volume %(original)s to %(name)s"
msgstr ""

#: cinder/volume/drivers/dell/dell_storagecenter_api.py:1885
msgid "User does not have permission to change Storage Profile selection."
msgstr ""

#: cinder/volume/drivers/dell/dell_storagecenter_api.py:1892
#, python-format
msgid "Storage Profile %s was not found."
msgstr ""

#: cinder/volume/drivers/dell/dell_storagecenter_api.py:1899
msgid "Default Storage Profile was not found."
msgstr ""

#: cinder/volume/drivers/dell/dell_storagecenter_api.py:1913
#, python-format
msgid "Error changing Storage Profile for volume %(original)s to %(name)s"
msgstr ""

#: cinder/volume/drivers/dell/dell_storagecenter_api.py:1975
#, python-format
msgid "Multiple replay profiles under name %s"
msgstr ""

#: cinder/volume/drivers/dell/dell_storagecenter_api.py:2021
#, python-format
msgid "Unable to delete profile %s."
msgstr ""

#: cinder/volume/drivers/dell/dell_storagecenter_api.py:2092
#, python-format
msgid "Failed to add %s to cg."
msgstr ""

#: cinder/volume/drivers/dell/dell_storagecenter_api.py:2110
#, python-format
msgid "Failed to remove %s from cg."
msgstr ""

#: cinder/volume/drivers/dell/dell_storagecenter_api.py:2229
#, python-format
msgid "Unable to locate snapshot %s"
msgstr ""

#: cinder/volume/drivers/dell/dell_storagecenter_api.py:2435
#, python-format
msgid "Unable to find or create QoS Node named %s"
msgstr ""

#: cinder/volume/drivers/dell/dell_storagecenter_api.py:2506
#, python-format
msgid "Unable to delete replication for %(vol)s to %(dest)s."
msgstr ""

#: cinder/volume/drivers/dell/dell_storagecenter_api.py:2534
#, python-format
msgid "Unable to find disk folder %(name)s on %(ssn)s"
msgstr ""

#: cinder/volume/drivers/dell/dell_storagecenter_api.py:2584
#, python-format
msgid "Unable to replicate %(volname)s to %(destsc)s"
msgstr ""

#: cinder/volume/drivers/dell/dell_storagecenter_common.py:250
#: cinder/volume/drivers/dell/dell_storagecenter_common.py:399
#: cinder/volume/drivers/dell/dell_storagecenter_common.py:451
#, python-format
msgid "Failed to create volume %s"
msgstr ""

#: cinder/volume/drivers/dell/dell_storagecenter_common.py:309
#, python-format
msgid "Failed to delete volume %s"
msgstr ""

#: cinder/volume/drivers/dell/dell_storagecenter_common.py:505
#, python-format
msgid "Failed to ensure export of volume %s"
msgstr ""

#: cinder/volume/drivers/dell/dell_storagecenter_common.py:689
#: cinder/volume/drivers/dell/dell_storagecenter_common.py:728
#, python-format
msgid "Cannot find Consistency Group %s"
msgstr ""

#: cinder/volume/drivers/dell/dell_storagecenter_common.py:726
#, python-format
msgid "Failed to snap Consistency Group %s"
msgstr ""

#: cinder/volume/drivers/dell/dell_storagecenter_common.py:905
#, python-format
msgid "Retype unable to find volume %s."
msgstr ""

#: cinder/volume/drivers/dell/dell_storagecenter_common.py:917
msgid "Failed to update storage profile"
msgstr ""

#: cinder/volume/drivers/dell/dell_storagecenter_common.py:928
msgid "Failed to update replay profiles"
msgstr ""

#: cinder/volume/drivers/dell/dell_storagecenter_common.py:956
msgid "Failed to apply replication:activereplay setting"
msgstr ""

#: cinder/volume/drivers/dell/dell_storagecenter_common.py:989
#, python-format
msgid "Unable to resume replication on volume %(vol)s to SC %(ssn)s"
msgstr ""

#: cinder/volume/drivers/dell/dell_storagecenter_common.py:996
#: cinder/volume/drivers/dell/dell_storagecenter_common.py:1029
#, python-format
msgid "Volume %s not found"
msgstr ""

#: cinder/volume/drivers/dell/dell_storagecenter_common.py:998
#: cinder/volume/drivers/dell/dell_storagecenter_common.py:1031
#, python-format
msgid "Replication not enabled or no replication destinations found.  %s"
msgstr ""

#: cinder/volume/drivers/dell/dell_storagecenter_common.py:1022
#, python-format
msgid "Unable to pause replication on volume %(vol)s to SC %(ssn)s"
msgstr ""

#: cinder/volume/drivers/dell/dell_storagecenter_common.py:1147
#, python-format
msgid "Unable to break replication from %(from)s to %(to)d."
msgstr ""

#: cinder/volume/drivers/dell/dell_storagecenter_common.py:1152
msgid "Unable to find valid destination."
msgstr ""

#: cinder/volume/drivers/dell/dell_storagecenter_fc.py:106
msgid "Lun mapping returned null!"
msgstr ""

#: cinder/volume/drivers/dell/dell_storagecenter_fc.py:110
msgid "Failed to initialize connection."
msgstr ""

#: cinder/volume/drivers/dell/dell_storagecenter_fc.py:155
msgid "Failed to terminate connection"
msgstr ""

#: cinder/volume/drivers/dell/dell_storagecenter_iscsi.py:132
msgid "Failed to initialize connection"
msgstr ""

#: cinder/volume/drivers/dell/dell_storagecenter_iscsi.py:165
#, python-format
msgid "Failed to terminate connection %(initiator)s %(vol)s"
msgstr ""

#: cinder/volume/drivers/dothill/dothill_client.py:273
#, python-format
msgid "Error in copying volume: %s"
msgstr ""

#: cinder/volume/drivers/dothill/dothill_common.py:179
#, python-format
msgid "Creation of volume %s failed."
msgstr ""

#: cinder/volume/drivers/dothill/dothill_common.py:204
msgid "Volume must be detached for clone operation."
msgstr ""

#: cinder/volume/drivers/dothill/dothill_common.py:226
#, python-format
msgid "Cloning of volume %s failed."
msgstr ""

#: cinder/volume/drivers/dothill/dothill_common.py:246
#, python-format
msgid "Create volume failed from snapshot: %s"
msgstr ""

#: cinder/volume/drivers/dothill/dothill_common.py:266
#, python-format
msgid "Deletion of volume %s failed."
msgstr ""

#: cinder/volume/drivers/dothill/dothill_common.py:328
#, python-format
msgid "Error mapping volume: %s"
msgstr ""

#: cinder/volume/drivers/dothill/dothill_common.py:344
#, python-format
msgid "Error unmapping volume: %s"
msgstr ""

#: cinder/volume/drivers/dothill/dothill_common.py:353
msgid "Error getting active FC target ports."
msgstr ""

#: cinder/volume/drivers/dothill/dothill_common.py:360
msgid "Error getting active ISCSI target iqns."
msgstr ""

#: cinder/volume/drivers/dothill/dothill_common.py:367
msgid "Error getting active ISCSI target portals."
msgstr ""

#: cinder/volume/drivers/dothill/dothill_common.py:384
#, python-format
msgid "Creation of snapshot failed for volume: %s"
msgstr ""

#: cinder/volume/drivers/dothill/dothill_common.py:401
#, python-format
msgid "Deleting snapshot %s failed"
msgstr ""

#: cinder/volume/drivers/dothill/dothill_common.py:423
#, python-format
msgid "Extension of volume %s failed."
msgstr ""

#: cinder/volume/drivers/dothill/dothill_common.py:432
msgid "Error getting chap record."
msgstr ""

#: cinder/volume/drivers/dothill/dothill_common.py:439
msgid "Error creating chap record."
msgstr ""

#: cinder/volume/drivers/dothill/dothill_common.py:484
#: cinder/volume/drivers/zfssa/zfssaiscsi.py:942
#, python-format
msgid "Error migrating volume: %s"
msgstr ""

#: cinder/volume/drivers/dothill/dothill_common.py:507
msgid "Error manage existing volume."
msgstr ""

#: cinder/volume/drivers/dothill/dothill_common.py:525
msgid "Error manage existing get volume size."
msgstr ""

#: cinder/volume/drivers/emc/emc_vmax_common.py:448
#, python-format
msgid "Error Attaching volume %(vol)s."
msgstr ""

#: cinder/volume/drivers/emc/emc_vmax_common.py:715
#, python-format
msgid "Volume %(name)s not found on the array. No volume to migrate using retype."
msgstr ""

#: cinder/volume/drivers/emc/emc_vmax_common.py:849
#, python-format
msgid ""
"Failed to return volume %(volumeName)s to original storage pool. Please "
"contact your system administrator to return it to the correct location."
msgstr ""

#: cinder/volume/drivers/emc/emc_vmax_common.py:938
#, python-format
msgid ""
"Unable to create or get default storage group for FAST policy: "
"%(fastPolicyName)s."
msgstr ""

#: cinder/volume/drivers/emc/emc_vmax_common.py:950
#, python-format
msgid ""
"Failed to verify that volume was added to storage group for FAST policy: "
"%(fastPolicyName)s."
msgstr ""

#: cinder/volume/drivers/emc/emc_vmax_common.py:992
#, python-format
msgid "Error finding target pool instance name for pool: %(targetPoolName)s."
msgstr ""

#: cinder/volume/drivers/emc/emc_vmax_common.py:1004
#, python-format
msgid "Error migrating volume: %(volumename)s. to target pool %(targetPoolName)s."
msgstr ""

#: cinder/volume/drivers/emc/emc_vmax_common.py:1019
#, python-format
msgid ""
"Volume : %(volumeName)s. was not successfully migrated to target pool "
"%(targetPoolName)s."
msgstr ""

#: cinder/volume/drivers/emc/emc_vmax_common.py:1099
#, python-format
msgid ""
"Failed to add %(volumeName)s to default storage group for fast policy "
"%(fastPolicyName)s."
msgstr ""

#: cinder/volume/drivers/emc/emc_vmax_common.py:1125
msgid "Error getting array, pool, SLO and workload."
msgstr ""

#: cinder/volume/drivers/emc/emc_vmax_common.py:1138
msgid "Error parsing array, pool, SLO and workload."
msgstr ""

#: cinder/volume/drivers/emc/emc_vmax_common.py:1141
#, python-format
msgid ""
"The source array : %(sourceArraySerialNumber)s does not match the target "
"array: %(targetArraySerialNumber)s skipping storage-assisted migration."
msgstr ""

#: cinder/volume/drivers/emc/emc_vmax_common.py:1150
#, python-format
msgid ""
"Only SLO/workload migration within the same SRP Pool is supported in this"
" version The source pool : %(sourcePoolName)s does not match the target "
"array: %(targetPoolName)s. Skipping storage-assisted migration."
msgstr ""

#: cinder/volume/drivers/emc/emc_vmax_common.py:1178
#, python-format
msgid ""
"No action required. Volume: %(volumeName)s is already part of "
"slo/workload combination: %(targetCombination)s."
msgstr ""

#: cinder/volume/drivers/emc/emc_vmax_common.py:1205
msgid "Error getting target pool name and array."
msgstr ""

#: cinder/volume/drivers/emc/emc_vmax_common.py:1217
msgid "Error parsing target pool name, array, and fast policy."
msgstr ""

#: cinder/volume/drivers/emc/emc_vmax_common.py:1221
#, python-format
msgid ""
"The source array : %(sourceArraySerialNumber)s does not match the target "
"array: %(targetArraySerialNumber)s, skipping storage-assisted migration."
msgstr ""

#: cinder/volume/drivers/emc/emc_vmax_common.py:1236
#, python-format
msgid ""
"No action required. Volume: %(volumeName)s is already part of pool: "
"%(pool)s."
msgstr ""

#: cinder/volume/drivers/emc/emc_vmax_common.py:1246
msgid "Only available volumes can be migrated between different protocols."
msgstr ""

#: cinder/volume/drivers/emc/emc_vmax_common.py:1600
#, python-format
msgid "Target end points do not exist for hardware Id: %(hardwareIdInstance)s."
msgstr ""

#: cinder/volume/drivers/emc/emc_vmax_common.py:2014
#, python-format
msgid "Unable to determine whether %(volumeName)s is composite or not."
msgstr ""

#: cinder/volume/drivers/emc/emc_vmax_common.py:2189
#, python-format
msgid "Volume %(name)s not found on the array. No volume to delete."
msgstr ""

#: cinder/volume/drivers/emc/emc_vmax_common.py:3055
#: cinder/volume/drivers/emc/emc_vmax_common.py:3178
#, python-format
msgid ""
"Volume %(name)s is not suitable for storage assisted migration using "
"retype."
msgstr ""

#: cinder/volume/drivers/emc/emc_vmax_common.py:3120
#, python-format
msgid ""
"Volume : %(volumeName)s has not been removed from source storage group "
"%(storageGroup)s."
msgstr ""

#: cinder/volume/drivers/emc/emc_vmax_common.py:3134
#, python-format
msgid "Failed to get or create storage group %(storageGroupName)s."
msgstr ""

#: cinder/volume/drivers/emc/emc_vmax_common.py:3147
#, python-format
msgid ""
"Volume : %(volumeName)s has not been added to target storage group "
"%(storageGroup)s."
msgstr ""

#: cinder/volume/drivers/emc/emc_vmax_common.py:3419
#, python-format
msgid ""
"Failed to Roll back to re-add volume %(volumeName)s to default storage "
"group for fast policy %(fastPolicyName)s. Please contact your sysadmin to"
" get the volume returned to the default storage group."
msgstr ""

#: cinder/volume/drivers/emc/emc_vmax_common.py:4245
#, python-format
msgid "Exception: %(ex)s"
msgstr ""

#: cinder/volume/drivers/emc/emc_vmax_common.py:4264
#, python-format
msgid "Volume %(name)s not found on the array."
msgstr ""

#: cinder/volume/drivers/emc/emc_vmax_fast.py:53
msgid "Cannot determine whether Tiering Policy is supported on this array."
msgstr ""

#: cinder/volume/drivers/emc/emc_vmax_fast.py:57
msgid "Tiering Policy is not supported on this array."
msgstr ""

#: cinder/volume/drivers/emc/emc_vmax_fast.py:90
msgid "Cannot determine if Tiering Policies are supported."
msgstr ""

#: cinder/volume/drivers/emc/emc_vmax_fast.py:116
msgid "FAST is not supported on this array."
msgstr ""

#: cinder/volume/drivers/emc/emc_vmax_fast.py:130
#, python-format
msgid "Unable to find default storage group for FAST policy : %(fastPolicyName)s."
msgstr ""

#: cinder/volume/drivers/emc/emc_vmax_fast.py:180
#, python-format
msgid "Unable to get default storage group %(defaultSgName)s."
msgstr ""

#: cinder/volume/drivers/emc/emc_vmax_fast.py:217
#, python-format
msgid "Failed to create a first volume for storage group : %(storageGroupName)s."
msgstr ""

#: cinder/volume/drivers/emc/emc_vmax_fast.py:228
#, python-format
msgid ""
"Failed to create default storage group for FAST policy : "
"%(fastPolicyName)s."
msgstr ""

#: cinder/volume/drivers/emc/emc_vmax_fast.py:243
#, python-format
msgid "Unable to get policy rule for fast policy: %(fastPolicyName)s."
msgstr ""

#: cinder/volume/drivers/emc/emc_vmax_fast.py:283
msgid "Unable to get associated pool of volume."
msgstr ""

#: cinder/volume/drivers/emc/emc_vmax_fast.py:506
#, python-format
msgid "Cannot find the fast policy %(fastPolicyName)s."
msgstr ""

#: cinder/volume/drivers/emc/emc_vmax_fast.py:524
#, python-format
msgid ""
"Failed to add storage group %(storageGroupInstanceName)s to tier policy "
"rule %(tierPolicyRuleInstanceName)s."
msgstr ""

#: cinder/volume/drivers/emc/emc_vmax_fast.py:591
#, python-format
msgid "Error disassociating storage group from policy: %s."
msgstr ""

#: cinder/volume/drivers/emc/emc_vmax_fast.py:667
#, python-format
msgid "Exception: %s."
msgstr ""

#: cinder/volume/drivers/emc/emc_vmax_iscsi.py:201
msgid "The list of iscsi_ip_addresses is empty"
msgstr ""

#: cinder/volume/drivers/emc/emc_vmax_masking.py:124
#, python-format
msgid ""
"Masking View creation or retrieval was not successful for masking view "
"%(maskingViewName)s. Attempting rollback."
msgstr ""

#: cinder/volume/drivers/emc/emc_vmax_masking.py:701
#, python-format
msgid "Looks like masking view: %(maskingViewName)s has recently been deleted."
msgstr ""

#: cinder/volume/drivers/emc/emc_vmax_masking.py:758
#, python-format
msgid ""
"Cannot add and verify tier policy association for storage group : "
"%(storageGroupName)s to FAST policy : %(fastPolicyName)s."
msgstr ""

#: cinder/volume/drivers/emc/emc_vmax_masking.py:766
#, python-format
msgid "Cannot get storage Group from job : %(storageGroupName)s."
msgstr ""

#: cinder/volume/drivers/emc/emc_vmax_masking.py:801
#, python-format
msgid ""
"Could not find port group : %(portGroupName)s. Check that the EMC "
"configuration file has the correct port group name."
msgstr ""

#: cinder/volume/drivers/emc/emc_vmax_masking.py:1177
#, python-format
msgid ""
"Cannot find a portGroup with name %(pgGroupName)s. The port group for a "
"masking view must be pre-defined."
msgstr ""

#: cinder/volume/drivers/emc/emc_vmax_masking.py:1206
#, python-format
msgid "Cannot create or find an initiator group with name %(igGroupName)s."
msgstr ""

#: cinder/volume/drivers/emc/emc_vmax_masking.py:1234
#, python-format
msgid ""
"Cannot find the new masking view just created with name "
"%(maskingViewName)s."
msgstr ""

#: cinder/volume/drivers/emc/emc_vmax_masking.py:1290
#, python-format
msgid ""
"Failed to Roll back to re-add volume %(volumeName)s to default storage "
"group for fast policy %(fastPolicyName)s: Please contact your sys admin "
"to get the volume re-added manually."
msgstr ""

#: cinder/volume/drivers/emc/emc_vmax_masking.py:1424
#, python-format
msgid "Failed to create hardware id(s) on %(storageSystemName)s."
msgstr ""

#: cinder/volume/drivers/emc/emc_vmax_masking.py:1456
#, python-format
msgid ""
"One of the components of the original masking view %(maskingViewName)s "
"cannot be retrieved so please contact your system administrator to check "
"that the correct initiator(s) are part of masking."
msgstr ""

#: cinder/volume/drivers/emc/emc_vmax_masking.py:1686
#, python-format
msgid ""
"Failed to remove %(volumeName)s from the default storage group for the "
"FAST Policy."
msgstr ""

#: cinder/volume/drivers/emc/emc_vmax_masking.py:2644
#, python-format
msgid "Cannot get port group from masking view: %(maskingViewName)s. "
msgstr ""

#: cinder/volume/drivers/emc/emc_vmax_masking.py:2655
msgid "Cannot get port group name."
msgstr ""

#: cinder/volume/drivers/emc/emc_vmax_provision_v3.py:301
#, python-format
msgid ""
"Error Create Group: %(groupName)s. Return code: %(rc)lu.  Error: "
"%(error)s."
msgstr ""

#: cinder/volume/drivers/emc/emc_vmax_utils.py:321
#, python-format
msgid "_wait_for_job_complete failed after %(retries)d tries."
msgstr ""

#: cinder/volume/drivers/emc/emc_vmax_utils.py:415
#, python-format
msgid "_wait_for_sync failed after %(retries)d tries."
msgstr ""

#: cinder/volume/drivers/emc/emc_vmax_utils.py:490
msgid "Cannot get storage system."
msgstr ""

#: cinder/volume/drivers/emc/emc_vmax_utils.py:964
#, python-format
msgid "Unable to retrieve pool instance of %(poolName)s on array %(array)s."
msgstr ""

#: cinder/volume/drivers/emc/emc_vmax_utils.py:1175
msgid "Error parsing array from host capabilities."
msgstr ""

#: cinder/volume/drivers/emc/emc_vmax_utils.py:1506
#, python-format
msgid ""
"SLO: %(slo)s is not valid. Valid values are Bronze, Silver, Gold, "
"Platinum, Diamond, Optimized, NONE."
msgstr ""

#: cinder/volume/drivers/emc/emc_vmax_utils.py:1511
#, python-format
msgid ""
"Workload: %(workload)s is not valid. Valid values are DSS_REP, DSS, OLTP,"
" OLTP_REP, NONE."
msgstr ""

#: cinder/volume/drivers/emc/emc_vmax_utils.py:1644
#: cinder/volume/drivers/fujitsu/eternus_dx_common.py:2101
#: cinder/volume/drivers/hpe/hpe_3par_common.py:1849
#: cinder/volume/drivers/hpe/hpe_3par_common.py:1863
#: cinder/volume/drivers/hpe/hpe_3par_common.py:1866
#: cinder/volume/drivers/hpe/hpe_3par_common.py:1869
#: cinder/volume/drivers/hpe/hpe_3par_common.py:1872
#: cinder/volume/drivers/hpe/hpe_3par_common.py:2001
#: cinder/volume/drivers/hpe/hpe_3par_common.py:2033
#: cinder/volume/drivers/hpe/hpe_3par_common.py:2036
#: cinder/volume/drivers/hpe/hpe_3par_common.py:2094
#: cinder/volume/drivers/hpe/hpe_3par_common.py:2104
#: cinder/volume/drivers/hpe/hpe_3par_common.py:2107
#: cinder/volume/drivers/hpe/hpe_3par_common.py:2110
#: cinder/volume/drivers/hpe/hpe_3par_common.py:2187
#: cinder/volume/drivers/hpe/hpe_3par_common.py:2197
#: cinder/volume/drivers/hpe/hpe_3par_common.py:2200
#: cinder/volume/drivers/hpe/hpe_3par_common.py:2203
#: cinder/volume/drivers/hpe/hpe_3par_common.py:2241
#: cinder/volume/drivers/hpe/hpe_3par_common.py:2244
#: cinder/volume/drivers/hpe/hpe_3par_common.py:2454
#: cinder/volume/drivers/hpe/hpe_3par_common.py:2457
#: cinder/volume/drivers/hpe/hpe_3par_common.py:2460
#: cinder/volume/drivers/hpe/hpe_3par_common.py:2463
#: cinder/volume/drivers/hpe/hpe_3par_common.py:2476
#: cinder/volume/drivers/hpe/hpe_3par_common.py:2485
#: cinder/volume/drivers/hpe/hpe_3par_common.py:2532
#: cinder/volume/drivers/hpe/hpe_3par_common.py:2536
#: cinder/volume/drivers/hpe/hpe_lefthand_iscsi.py:1021
#, python-format
msgid "Exception: %s"
msgstr ""

#: cinder/volume/drivers/emc/emc_vmax_utils.py:1894
msgid ""
"Please check your xml for format or syntax errors. Please see "
"documentation for more details."
msgstr ""

#: cinder/volume/drivers/emc/emc_vmax_utils.py:1935
#, python-format
msgid "Array Serial Number must be in the file %(fileName)s."
msgstr ""

#: cinder/volume/drivers/emc/emc_vmax_utils.py:1941
#, python-format
msgid "PoolName must be in the file %(fileName)s."
msgstr ""

#: cinder/volume/drivers/emc/emc_vnx_cli.py:785
#, python-format
msgid "Error on enable compression on lun %s."
msgstr ""

#: cinder/volume/drivers/emc/emc_vnx_cli.py:796
#, python-format
msgid "Error on adding lun to consistency group. %s"
msgstr ""

#: cinder/volume/drivers/emc/emc_vnx_cli.py:1035
#, python-format
msgid "Can not add the lun %(lun)s to consistency group %(cg_name)s."
msgstr ""

#: cinder/volume/drivers/emc/emc_vnx_cli.py:1048
#, python-format
msgid "Can not remove LUNs %(luns)s in consistency group %(cg_name)s."
msgstr ""

#: cinder/volume/drivers/emc/emc_vnx_cli.py:1061
#, python-format
msgid "Can not place new LUNs %(luns)s in consistency group %(cg_name)s."
msgstr ""

#: cinder/volume/drivers/emc/emc_vnx_cli.py:1366
msgid "Failed to query migration status of LUN."
msgstr ""

#: cinder/volume/drivers/emc/emc_vnx_cli.py:1382
#, python-format
msgid "Migration of LUN %s failed to complete."
msgstr ""

#: cinder/volume/drivers/emc/emc_vnx_cli.py:1657
#, python-format
msgid "Invalid value for %(key)s, value is %(value)s."
msgstr ""

#: cinder/volume/drivers/emc/emc_vnx_cli.py:1696
#, python-format
msgid "Error happened during storage pool querying, %s."
msgstr ""

#: cinder/volume/drivers/emc/emc_vnx_cli.py:2396
msgid "The given extra_spec or valid_values is None."
msgstr ""

#: cinder/volume/drivers/emc/emc_vnx_cli.py:3133
#, python-format
msgid "Create consistency group %s failed."
msgstr ""

#: cinder/volume/drivers/emc/emc_vnx_cli.py:3151
#, python-format
msgid "Delete consistency group %s failed."
msgstr ""

#: cinder/volume/drivers/emc/emc_vnx_cli.py:3217
#, python-format
msgid "Create cg snapshot %s failed."
msgstr ""

#: cinder/volume/drivers/emc/emc_vnx_cli.py:3242
#, python-format
msgid "Delete cgsnapshot %s failed."
msgstr ""

#: cinder/volume/drivers/emc/emc_vnx_cli.py:3656
#, python-format
msgid "Failed to find available iSCSI targets for %s."
msgstr ""

#: cinder/volume/drivers/emc/scaleio.py:1129
#: cinder/volume/drivers/ibm/storwize_svc/storwize_svc_common.py:2867
#, python-format
msgid "Failed to delete the volume %(vol)s of CG. Exception: %(exception)s."
msgstr ""

#: cinder/volume/drivers/emc/scaleio.py:1174
#, python-format
msgid ""
"Failed to delete the snapshot %(snap)s of cgsnapshot: %(cgsnapshot_id)s. "
"Exception: %(exception)s."
msgstr ""

#: cinder/volume/drivers/emc/xtremio.py:161
#, python-format
msgid "can't create 2 volumes with the same name, %s"
msgstr ""

#: cinder/volume/drivers/emc/xtremio.py:166
#, python-format
msgid "Can't find volume to map %(key)s, %(msg)s"
msgstr ""

#: cinder/volume/drivers/emc/xtremio.py:337
msgid "Failed to rename the created snapshot, reverting."
msgstr ""

#: cinder/volume/drivers/fujitsu/eternus_dx_common.py:43
msgid "import pywbem failed!! pywbem is necessary for this volume driver."
msgstr ""

#: cinder/volume/drivers/fujitsu/eternus_dx_common.py:2090
#, python-format
msgid "_wait_for_job_complete, failed after %(retries)d tries."
msgstr ""

#: cinder/volume/drivers/hitachi/hbsd_basiclib.py:171
#, python-format
msgid "MSGID%(id)04d-E: %(msg)s"
msgstr ""

#: cinder/volume/drivers/hitachi/hbsd_common.py:727
#, python-format
msgid "Failed to update volume status: %s"
msgstr ""

#: cinder/volume/drivers/hitachi/hbsd_horcm.py:229
msgid "Failed to shutdown horcm."
msgstr ""

#: cinder/volume/drivers/hitachi/hbsd_horcm.py:297
msgid "horcm command timeout."
msgstr ""

#: cinder/volume/drivers/hitachi/hbsd_horcm.py:304
msgid "Failed to authenticate user."
msgstr ""

#: cinder/volume/drivers/hitachi/hbsd_horcm.py:313
msgid "Failed to start horcm."
msgstr ""

#: cinder/volume/drivers/hitachi/hbsd_horcm.py:317
msgid "Unexpected error occurs in horcm."
msgstr ""

#: cinder/volume/drivers/hitachi/hbsd_iscsi.py:182
#, python-format
msgid "Failed to add target(port: %s)"
msgstr ""

#: cinder/volume/drivers/hitachi/hbsd_snm2.py:76
msgid "snm2 command timeout."
msgstr ""

#: cinder/volume/drivers/hitachi/hbsd_snm2.py:90
msgid "Unexpected error occurs in snm2."
msgstr ""

#: cinder/volume/drivers/hitachi/hnas_backend.py:327
#, python-format
msgid "Error getting iSCSI target info from EVS %(evs)s."
msgstr ""

#: cinder/volume/drivers/hitachi/hnas_iscsi.py:251
#, python-format
msgid "No configuration found for service: %s."
msgstr ""

#: cinder/volume/drivers/hitachi/hnas_iscsi.py:316
msgid "No more targets avaliable."
msgstr ""

#: cinder/volume/drivers/hitachi/hnas_iscsi.py:456
#, python-format
msgid "HDP not found: %s"
msgstr ""

#: cinder/volume/drivers/hitachi/hnas_iscsi.py:517
#, python-format
msgid "iSCSI portal not found for service: %s"
msgstr ""

#: cinder/volume/drivers/hitachi/hnas_iscsi.py:631
msgid "delete_vol: provider location empty."
msgstr ""

#: cinder/volume/drivers/hitachi/hnas_iscsi.py:808
#, python-format
msgid "Array mismatch %(myid)s vs %(arid)s"
msgstr ""

#: cinder/volume/drivers/hitachi/hnas_nfs.py:221
#, python-format
msgid "No configuration found for service: %s"
msgstr ""

#: cinder/volume/drivers/hitachi/hnas_nfs.py:500
#, python-format
msgid "NFS share %(share)s has no service entry: %(svc)s -> %(hdp)s"
msgstr ""

#: cinder/volume/drivers/hitachi/hnas_nfs.py:601
#, python-format
msgid "Invalid hostname %(host)s"
msgstr ""

#: cinder/volume/drivers/hitachi/hnas_nfs.py:794
#, python-format
msgid "The NFS Volume %(cr)s does not exist."
msgstr ""

#: cinder/volume/drivers/hpe/hpe_3par_common.py:414
#, python-format
msgid ""
"The primary array must have an API version of %(min_ver)s or higher, but "
"is only on %(current_ver)s, therefore replication is not supported."
msgstr ""

#: cinder/volume/drivers/hpe/hpe_3par_common.py:568
#, python-format
msgid "Conflict detected in Virtual Volume Set %(volume_set)s: %(error)s"
msgstr ""

#: cinder/volume/drivers/hpe/hpe_3par_common.py:581
#, python-format
msgid "There was an error deleting volume %(id)s: %(error)."
msgstr ""

#: cinder/volume/drivers/hpe/hpe_3par_common.py:602
#: cinder/volume/drivers/hpe/hpe_3par_common.py:613
#, python-format
msgid "Virtual Volume Set %s does not exist."
msgstr ""

#: cinder/volume/drivers/hpe/hpe_3par_common.py:681
#: cinder/volume/drivers/hpe/hpe_lefthand_iscsi.py:566
#, python-format
msgid "There was an error deleting snapshot %(id)s: %(error)."
msgstr ""

#: cinder/volume/drivers/hpe/hpe_3par_common.py:1028
#, python-format
msgid "Error extending volume: %(vol)s. Exception: %(ex)s"
msgstr ""

#: cinder/volume/drivers/hpe/hpe_3par_common.py:1554
#, python-format
msgid "Error creating QOS rule %s"
msgstr ""

#: cinder/volume/drivers/hpe/hpe_3par_common.py:1587
#, python-format
msgid "Error setting Flash Cache policy to %s - exception"
msgstr ""

#: cinder/volume/drivers/hpe/hpe_3par_common.py:2167
#, python-format
msgid "Error extending volume %(id)s. Ex: %(ex)s"
msgstr ""

#: cinder/volume/drivers/hpe/hpe_3par_common.py:2300
#, python-format
msgid "Error attaching volume %s"
msgstr ""

#: cinder/volume/drivers/hpe/hpe_3par_common.py:2375
#, python-format
msgid ""
"Changing the volume name from %(tmp)s to %(orig)s failed because "
"%(reason)s"
msgstr ""

#: cinder/volume/drivers/hpe/hpe_3par_common.py:2874
msgid "Issuing a fail-over failed because replication is not properly configured."
msgstr ""

#: cinder/volume/drivers/hpe/hpe_3par_common.py:2921
#: cinder/volume/drivers/hpe/hpe_lefthand_iscsi.py:1462
#: cinder/volume/drivers/hpe/hpe_lefthand_iscsi.py:1602
#, python-format
msgid ""
"There was a problem with the failover (%(error)s) and it was "
"unsuccessful. Volume '%(volume)s will not be available on the failed over"
" target."
msgstr ""

#: cinder/volume/drivers/hpe/hpe_3par_common.py:3068
#, python-format
msgid "Could not log in to 3PAR array (%s) with the provided credentials."
msgstr ""

#: cinder/volume/drivers/hpe/hpe_3par_common.py:3093
#: cinder/volume/drivers/hpe/hpe_lefthand_iscsi.py:1680
msgid "There must be at least one valid replication device configured."
msgstr ""

#: cinder/volume/drivers/hpe/hpe_3par_common.py:3103
msgid ""
"Extra spec replication:mode must be set and must be either 'sync' or "
"'periodic'."
msgstr ""

#: cinder/volume/drivers/hpe/hpe_3par_common.py:3111
msgid ""
"Extra spec replication:sync_period must be greater than 299 and less than"
" 31622401 seconds."
msgstr ""

#: cinder/volume/drivers/hpe/hpe_3par_common.py:3553
#, python-format
msgid "Exception during snapCPG revert: %s"
msgstr ""

#: cinder/volume/drivers/hpe/hpe_3par_common.py:3625
#, python-format
msgid "Unexpected error when retype() tried to deleteVolumeSet(%s)"
msgstr ""

#: cinder/volume/drivers/hpe/hpe_3par_common.py:3647
#: cinder/volume/drivers/hpe/hpe_3par_common.py:3650
#, python-format
msgid "Unexpected error when retype() revert tried to deleteVolumeSet(%s)"
msgstr ""

#: cinder/volume/drivers/hpe/hpe_3par_common.py:3658
#, python-format
msgid ""
"%(exception)s: Exception during revert of retype for volume "
"%(volume_name)s. Original volume set/QOS settings may not have been fully"
" restored."
msgstr ""

#: cinder/volume/drivers/hpe/hpe_3par_common.py:3669
#, python-format
msgid ""
"%(exception)s: Exception during revert of retype for volume "
"%(volume_name)s. Failed to remove from new volume set %(new_vvs)s."
msgstr ""

#: cinder/volume/drivers/hpe/hpe_3par_iscsi.py:679
#, python-format
msgid "Volume %s doesn't exist on array."
msgstr ""

#: cinder/volume/drivers/hpe/hpe_lefthand_iscsi.py:424
msgid "Volume did not exist. It will not be deleted"
msgstr ""

#: cinder/volume/drivers/hpe/hpe_lefthand_iscsi.py:467
#, python-format
msgid "There was an error deleting volume %(id)s: %(error)s."
msgstr ""

#: cinder/volume/drivers/hpe/hpe_lefthand_iscsi.py:504
#, python-format
msgid "Could not find volume with name %(name)s. Error: %(error)s"
msgstr ""

#: cinder/volume/drivers/hpe/hpe_lefthand_iscsi.py:530
#, python-format
msgid "Could not create snapshot set. Error: '%s'"
msgstr ""

#: cinder/volume/drivers/hpe/hpe_lefthand_iscsi.py:562
msgid "The snapshot cannot be deleted because it is a clone point."
msgstr ""

#: cinder/volume/drivers/hpe/hpe_lefthand_iscsi.py:601
msgid "Snapshot did not exist. It will not be deleted"
msgstr ""

#: cinder/volume/drivers/hpe/hpe_lefthand_iscsi.py:827
#, python-format
msgid "'%(value)s' is an invalid value for extra spec '%(key)s'"
msgstr ""

#: cinder/volume/drivers/hpe/hpe_lefthand_iscsi.py:1052
#, python-format
msgid ""
"Changing the volume name from %(tmp)s to %(orig)s failed because "
"%(reason)s."
msgstr ""

#: cinder/volume/drivers/hpe/hpe_lefthand_iscsi.py:1550
#, python-format
msgid "Could not log in to LeftHand array (%s) with the provided credentials."
msgstr ""

#: cinder/volume/drivers/huawei/huawei_driver.py:188
msgid ""
"Extra specs must be specified as replication_type='<in> sync' or '<in> "
"async'."
msgstr ""

#: cinder/volume/drivers/huawei/huawei_driver.py:192
#, python-format
msgid "Extra specs must be specified as capabilities:%s='<is> True'."
msgstr ""

#: cinder/volume/drivers/huawei/huawei_driver.py:279
#, python-format
msgid "Create hypermetro error: %s."
msgstr ""

#: cinder/volume/drivers/huawei/huawei_driver.py:290
msgid "Create replication volume error."
msgstr ""

#: cinder/volume/drivers/huawei/huawei_driver.py:351
#, python-format
msgid "Delete hypermetro error: %s."
msgstr ""

#: cinder/volume/drivers/huawei/huawei_driver.py:362
msgid "Delete replication error."
msgstr ""

#: cinder/volume/drivers/huawei/huawei_driver.py:406
msgid "Get LUN migration error."
msgstr ""

#: cinder/volume/drivers/huawei/huawei_driver.py:464
#, python-format
msgid "Unable to rename lun %s on array."
msgstr ""

#: cinder/volume/drivers/huawei/huawei_driver.py:769
msgid "Retype volume error. Delete replication failed."
msgstr ""

#: cinder/volume/drivers/huawei/huawei_driver.py:786
msgid "Retype volume error."
msgstr ""

#: cinder/volume/drivers/huawei/huawei_driver.py:799
msgid "Retype volume error. Create replication failed."
msgstr ""

#: cinder/volume/drivers/huawei/huawei_driver.py:1227
msgid "Manage exist volume failed."
msgstr ""

#: cinder/volume/drivers/huawei/huawei_driver.py:1257
#, python-format
msgid "Can't find LUN on the array for volume: %s."
msgstr ""

#: cinder/volume/drivers/huawei/replication.py:530
#, python-format
msgid "Create pair failed. Error: %s."
msgstr ""

#: cinder/volume/drivers/huawei/replication.py:540
#, python-format
msgid "Start synchronization failed. Error: %s."
msgstr ""

#: cinder/volume/drivers/huawei/rest_client.py:88
#, python-format
msgid "Bad response from server: %(url)s. Error: %(err)s"
msgstr ""

#: cinder/volume/drivers/huawei/rest_client.py:98
#, python-format
msgid "JSON transfer error: %s."
msgstr ""

#: cinder/volume/drivers/huawei/rest_client.py:116
#, python-format
msgid ""
"Login error. URL: %(url)s\n"
"Reason: %(reason)s."
msgstr ""

#: cinder/volume/drivers/huawei/rest_client.py:147
msgid "Can't open the recent url, relogin."
msgstr ""

#: cinder/volume/drivers/huawei/rest_client.py:447
msgid ""
"Error occurred when adding hostgroup and lungroup to view. Remove lun "
"from lungroup now."
msgstr ""

#: cinder/volume/drivers/huawei/rest_client.py:600
#, python-format
msgid "JSON transfer data error. %s."
msgstr ""

#: cinder/volume/drivers/huawei/rest_client.py:1800
msgid "Can not open the recent url, login again."
msgstr ""

#: cinder/volume/drivers/ibm/flashsystem_common.py:229
#, python-format
msgid "Failed to copy %(src)s to %(dest)s."
msgstr ""

#: cinder/volume/drivers/ibm/flashsystem_common.py:664
#, python-format
msgid ""
"%(fun)s: Failed with unexpected CLI output.\n"
" Command: %(cmd)s\n"
"stdout: %(out)s\n"
"stderr: %(err)s\n"
msgstr ""

#: cinder/volume/drivers/ibm/flashsystem_common.py:824
#, python-format
msgid ""
"_unmap_vdisk_from_host: No mapping of volume %(vol_name)s to host "
"%(host_name)s found."
msgstr ""

#: cinder/volume/drivers/ibm/flashsystem_fc.py:282
#, python-format
msgid ""
"initialize_connection: Failed to collect return properties for volume "
"%(vol)s and connector %(conn)s."
msgstr ""

#: cinder/volume/drivers/ibm/flashsystem_fc.py:373
msgid "The connector does not contain the required information: wwpns is missing"
msgstr ""

#: cinder/volume/drivers/ibm/flashsystem_iscsi.py:247
#, python-format
msgid ""
"Failed to collect return properties for volume %(vol)s and connector "
"%(conn)s."
msgstr ""

#: cinder/volume/drivers/ibm/flashsystem_iscsi.py:381
msgid ""
"The connector does not contain the required information: initiator is "
"missing"
msgstr ""

#: cinder/volume/drivers/ibm/gpfs.py:143
#, python-format
msgid "Failed to issue mmgetstate command, error: %s."
msgstr ""

#: cinder/volume/drivers/ibm/gpfs.py:154
#, python-format
msgid "GPFS is not active.  Detailed output: %s."
msgstr ""

#: cinder/volume/drivers/ibm/gpfs.py:166
#, python-format
msgid "Failed to issue df command for path %(path)s, error: %(error)s."
msgstr ""

#: cinder/volume/drivers/ibm/gpfs.py:181 cinder/volume/drivers/ibm/gpfs.py:267
#, python-format
msgid "Failed to issue mmlsconfig command, error: %s."
msgstr ""

#: cinder/volume/drivers/ibm/gpfs.py:191
#, python-format
msgid "Failed to issue mmlsattr command on path %(path)s, error: %(error)s"
msgstr ""

#: cinder/volume/drivers/ibm/gpfs.py:246
#, python-format
msgid "Failed to issue mmlsfs command for path %(path)s, error: %(error)s."
msgstr ""

#: cinder/volume/drivers/ibm/gpfs.py:284
#, python-format
msgid "Failed to issue mmlsattr command for path %(path)s, error: %(error)s."
msgstr ""

#: cinder/volume/drivers/ibm/gpfs.py:768
#, python-format
msgid "Failed to issue mmlsfs command, error: %s."
msgstr ""

#: cinder/volume/drivers/ibm/gpfs.py:933
#, python-format
msgid "Failed to resize volume %(volume_id)s, error: %(error)s."
msgstr ""

#: cinder/volume/drivers/ibm/gpfs.py:1014
#, python-format
msgid ""
"Driver-based migration of volume %(vol)s failed. Move from %(src)s to "
"%(dst)s failed with error: %(error)s."
msgstr ""

#: cinder/volume/drivers/ibm/storwize_svc/replication.py:307
#: cinder/volume/drivers/ibm/storwize_svc/storwize_svc_common.py:2024
#: cinder/volume/drivers/ibm/storwize_svc/storwize_svc_common.py:2074
#: cinder/volume/drivers/san/san.py:150
#: cinder/zonemanager/drivers/brocade/brcd_fc_zone_client_cli.py:427
#: cinder/zonemanager/drivers/cisco/cisco_fc_san_lookup_service.py:269
#, python-format
msgid "Error running SSH command: %s"
msgstr ""

#: cinder/volume/drivers/ibm/storwize_svc/replication.py:400
msgid "A valid secondary target MUST be specified in order to failover."
msgstr ""

#: cinder/volume/drivers/ibm/storwize_svc/storwize_svc_common.py:266
msgid ""
"storwize_svc_multihostmap_enabled is set to False, not allowing multi "
"host mapping."
msgstr ""

#: cinder/volume/drivers/ibm/storwize_svc/storwize_svc_common.py:273
msgid "Error mapping VDisk-to-host"
msgstr ""

#: cinder/volume/drivers/ibm/storwize_svc/storwize_svc_common.py:966
msgid "Protocol must be specified as '<in> iSCSI' or '<in> FC'."
msgstr ""

#: cinder/volume/drivers/ibm/storwize_svc/storwize_svc_common.py:981
msgid "Replication must be specified as '<is> True' or '<is> False'."
msgstr ""

#: cinder/volume/drivers/ibm/storwize_svc/storwize_svc_common.py:1238
#, python-format
msgid "Failed to create CGSnapshot. Exception: %s."
msgstr ""

#: cinder/volume/drivers/ibm/storwize_svc/storwize_svc_common.py:1254
#, python-format
msgid ""
"Failed to delete the snapshot %(snap)s of CGSnapshot. Exception: "
"%(exception)s."
msgstr ""

#: cinder/volume/drivers/ibm/storwize_svc/storwize_svc_common.py:1315
#, python-format
msgid "Failed to create CG from CGsnapshot. Exception: %s"
msgstr ""

#: cinder/volume/drivers/ibm/storwize_svc/storwize_svc_common.py:2056
#, python-format
msgid "Error has occurred: %s"
msgstr ""

#: cinder/volume/drivers/ibm/storwize_svc/storwize_svc_common.py:2084
#, python-format
msgid "ensure_export: Volume %s not found on storage."
msgstr ""

#: cinder/volume/drivers/ibm/storwize_svc/storwize_svc_common.py:2301
#, python-format
msgid ""
"_rm_vdisk_copy_op: Volume %s does not have any registered vdisk copy "
"operations."
msgstr ""

#: cinder/volume/drivers/ibm/storwize_svc/storwize_svc_common.py:2305
#, python-format
msgid ""
"_rm_vdisk_copy_op: Volume %(vol)s does not have the specified vdisk copy "
"operation: orig=%(orig)s new=%(new)s."
msgstr ""

#: cinder/volume/drivers/ibm/storwize_svc/storwize_svc_common.py:2316
#, python-format
msgid ""
"_rm_vdisk_copy_op: Volume metadata %s does not have any registered vdisk "
"copy operations."
msgstr ""

#: cinder/volume/drivers/ibm/storwize_svc/storwize_svc_common.py:2324
#, python-format
msgid ""
"_rm_vdisk_copy_op: Volume %(vol)s metadata does not have the specified "
"vdisk copy operation: orig=%(orig)s new=%(new)s."
msgstr ""

#: cinder/volume/drivers/ibm/storwize_svc/storwize_svc_common.py:2527
#, python-format
msgid ""
"The replication mode of %(type)s has not successfully established "
"partnership with the replica Storwize target %(stor)s."
msgstr ""

#: cinder/volume/drivers/ibm/storwize_svc/storwize_svc_fc.py:128
#: cinder/volume/drivers/ibm/storwize_svc/storwize_svc_iscsi.py:132
msgid "The connector does not contain the required information."
msgstr ""

#: cinder/volume/drivers/ibm/storwize_svc/storwize_svc_fc.py:172
#: cinder/volume/drivers/ibm/storwize_svc/storwize_svc_iscsi.py:183
#, python-format
msgid "Did not find expected column name in lsvdisk: %s."
msgstr ""

#: cinder/volume/drivers/ibm/storwize_svc/storwize_svc_fc.py:227
#: cinder/volume/drivers/ibm/storwize_svc/storwize_svc_iscsi.py:237
#, python-format
msgid ""
"initialize_connection: Failed to collect return properties for volume "
"%(vol)s and connector %(conn)s.\n"
msgstr ""

#: cinder/volume/drivers/infortrend/eonstor_ds_cli/cli_factory.py:48
#, python-format
msgid "Retry %(retry)s times: %(method)s Failed %(rc)s: %(reason)s"
msgstr ""

#: cinder/volume/drivers/infortrend/eonstor_ds_cli/cli_factory.py:147
#, python-format
msgid "Error on execute command. Error code: %(exit_code)d Error msg: %(result)s"
msgstr ""

#: cinder/volume/drivers/infortrend/eonstor_ds_cli/cli_factory.py:222
#, python-format
msgid ""
"Error on execute %(command)s. Error code: %(exit_code)d Error msg: "
"%(result)s"
msgstr ""

#: cinder/volume/drivers/infortrend/eonstor_ds_cli/common_cli.py:1541
#, python-format
msgid "Can not discovery in %(target_ip)s with %(target_iqn)s."
msgstr ""

#: cinder/volume/drivers/infortrend/eonstor_ds_cli/common_cli.py:1700
msgid "Cannot detect replica status."
msgstr ""

#: cinder/volume/drivers/infortrend/eonstor_ds_cli/common_cli.py:1930
#, python-format
msgid "Failed to rename %(new_volume)s into %(volume)s."
msgstr ""

#: cinder/volume/drivers/netapp/utils.py:286
#, python-format
msgid "Cannot get QoS spec for volume %s."
msgstr ""

#: cinder/volume/drivers/netapp/dataontap/block_base.py:211
#, python-format
msgid "Exception creating LUN %(name)s in pool %(pool)s."
msgstr ""

#: cinder/volume/drivers/netapp/dataontap/block_base.py:328
#, python-format
msgid "Exception cloning volume %(name)s from source volume %(source)s."
msgstr ""

#: cinder/volume/drivers/netapp/dataontap/block_base.py:466
#, python-format
msgid "Message: %s"
msgstr ""

#: cinder/volume/drivers/netapp/dataontap/block_base.py:468
#, python-format
msgid "Error getting LUN attribute. Exception: %s"
msgstr ""

#: cinder/volume/drivers/netapp/dataontap/block_base.py:621
#, python-format
msgid "Failure deleting staged tmp LUN %s."
msgstr ""

#: cinder/volume/drivers/netapp/dataontap/block_base.py:624
#, python-format
msgid "Unknown exception in post clone resize LUN %s."
msgstr ""

#: cinder/volume/drivers/netapp/dataontap/block_base.py:626
#, python-format
msgid "Exception details: %s"
msgstr ""

#: cinder/volume/drivers/netapp/dataontap/block_base.py:1016
#, python-format
msgid "Volume %(vol) in the consistency group could not be deleted."
msgstr ""

#: cinder/volume/drivers/netapp/dataontap/nfs_base.py:123
#, python-format
msgid "Exception creating vol %(name)s on pool %(pool)s."
msgstr ""

#: cinder/volume/drivers/netapp/dataontap/nfs_base.py:168
#, python-format
msgid ""
"Exception creating volume %(name)s from source %(source)s on share "
"%(share)s."
msgstr ""

#: cinder/volume/drivers/netapp/dataontap/nfs_cmode.py:94
#, python-format
msgid "Setting QoS for %s failed"
msgstr ""

#: cinder/volume/drivers/netapp/dataontap/nfs_cmode.py:367
#, python-format
msgid ""
"Could not do delete of volume %s on filer, falling back to exec of \"rm\""
" command."
msgstr ""

#: cinder/volume/drivers/netapp/dataontap/nfs_cmode.py:373
#: cinder/volume/drivers/netapp/dataontap/nfs_cmode.py:403
#, python-format
msgid "Exec of \"rm\" command on backing file for %s was unsuccessful."
msgstr ""

#: cinder/volume/drivers/netapp/dataontap/nfs_cmode.py:397
#, python-format
msgid ""
"Could not do delete of snapshot %s on filer, falling back to exec of "
"\"rm\" command."
msgstr ""

#: cinder/volume/drivers/netapp/dataontap/nfs_cmode.py:446
#, python-format
msgid "Copy offload workflow unsuccessful. %s"
msgstr ""

#: cinder/volume/drivers/netapp/dataontap/nfs_cmode.py:501
#, python-format
msgid "Error in workflow copy from cache. %s."
msgstr ""

#: cinder/volume/drivers/netapp/dataontap/client/client_base.py:108
#, python-format
msgid "Error provisioning volume %(lun_name)s on %(volume_name)s. Details: %(ex)s"
msgstr ""

#: cinder/volume/drivers/netapp/dataontap/client/client_base.py:208
#, python-format
msgid "LUN %(path)s geometry failed. Message - %(msg)s"
msgstr ""

#: cinder/volume/drivers/netapp/dataontap/performance/perf_7mode.py:51
#: cinder/volume/drivers/netapp/dataontap/performance/perf_cmode.py:58
msgid ""
"Could not get performance base counter name. Performance-based scheduler "
"functions may not be available."
msgstr ""

#: cinder/volume/drivers/netapp/dataontap/performance/perf_7mode.py:91
#: cinder/volume/drivers/netapp/dataontap/performance/perf_cmode.py:147
#, python-format
msgid "Could not get utilization counters from node %s"
msgstr ""

#: cinder/volume/drivers/netapp/dataontap/performance/perf_base.py:86
#, python-format
msgid "Could not calculate node utilization for node %s."
msgstr ""

#: cinder/volume/drivers/netapp/eseries/client.py:88
#, python-format
msgid "Unexpected error while invoking web service. Error - %s."
msgstr ""

#: cinder/volume/drivers/netapp/eseries/library.py:254
#, python-format
msgid "Error resolving host %(host)s. Error - %(e)s."
msgstr ""

#: cinder/volume/drivers/netapp/eseries/library.py:586
#: cinder/volume/drivers/netapp/eseries/library.py:624
#, python-format
msgid "Error creating volume. Msg - %s."
msgstr ""

#: cinder/volume/drivers/netapp/eseries/library.py:604
#, python-format
msgid "Error cleaning up failed volume creation.  Msg - %s."
msgstr ""

#: cinder/volume/drivers/netapp/eseries/library.py:654
#, python-format
msgid "Failure restarting snap vol. Error: %s."
msgstr ""

#: cinder/volume/drivers/netapp/eseries/library.py:682
#, python-format
msgid "Vol copy job status %s."
msgstr ""

#: cinder/volume/drivers/nexenta/iscsi.py:278
#: cinder/volume/drivers/nexenta/nfs.py:420
#: cinder/volume/drivers/nexenta/ns5/nfs.py:326
#, python-format
msgid "Volume creation failed, deleting created snapshot %(volume_name)s@%(name)s"
msgstr ""

#: cinder/volume/drivers/nexenta/iscsi.py:457
#: cinder/volume/drivers/nexenta/nfs.py:308
#, python-format
msgid "Error trying to change %(opt)s from %(old)s to %(new)s"
msgstr ""

#: cinder/volume/drivers/nexenta/nexentaedge/iscsi.py:105
#, python-format
msgid "No VIP configured for service %s"
msgstr ""

#: cinder/volume/drivers/nexenta/nexentaedge/iscsi.py:112
#, python-format
msgid "Error verifying iSCSI service %(serv)s on host %(hst)s"
msgstr ""

#: cinder/volume/drivers/nexenta/nexentaedge/iscsi.py:121
#, python-format
msgid "Error verifying LUN container %(bkt)s"
msgstr ""

#: cinder/volume/drivers/nexenta/nexentaedge/iscsi.py:133
#, python-format
msgid "Error retrieving LUN %(vol)s number"
msgstr ""

#: cinder/volume/drivers/nexenta/nexentaedge/iscsi.py:159
msgid "Error creating volume"
msgstr ""

#: cinder/volume/drivers/nexenta/nexentaedge/iscsi.py:168
msgid "Error deleting volume"
msgstr ""

#: cinder/volume/drivers/nexenta/nexentaedge/iscsi.py:178
msgid "Error extending volume"
msgstr ""

#: cinder/volume/drivers/nexenta/nexentaedge/iscsi.py:192
msgid "Error cloning volume"
msgstr ""

#: cinder/volume/drivers/nexenta/nexentaedge/iscsi.py:218
msgid "Error deleting snapshot"
msgstr ""

#: cinder/volume/drivers/nexenta/nexentaedge/iscsi.py:238
msgid "Error creating cloned volume"
msgstr ""

#: cinder/volume/drivers/nexenta/ns5/iscsi.py:345
#, python-format
msgid "Volume creation failed, deleting created snapshot %s"
msgstr ""

#: cinder/volume/drivers/prophetstor/dpl_fc.py:59
#, python-format
msgid "Failed to get fiber channel info from storage due to %(stat)s"
msgstr ""

#: cinder/volume/drivers/prophetstor/dpl_fc.py:84
#, python-format
msgid "Failed to get fiber channel target from storage server due to %(stat)s"
msgstr ""

#: cinder/volume/drivers/prophetstor/dpl_fc.py:102
#, python-format
msgid "Failed to get target wwpns from storage due to %(stat)s"
msgstr ""

#: cinder/volume/drivers/prophetstor/dpl_fc.py:120
msgid "Failed to get sns table"
msgstr ""

#: cinder/volume/drivers/prophetstor/dpl_fc.py:148
#, python-format
msgid ""
"Volume %(volumeid)s failed to send assign command, ret: %(status)s "
"output: %(output)s"
msgstr ""

#: cinder/volume/drivers/prophetstor/dpl_fc.py:288
#, python-format
msgid "Failed to export fiber channel target due to %s"
msgstr ""

#: cinder/volume/drivers/prophetstor/dplcommon.py:97
#, python-format
msgid "JSON encode params %(param)s error: %(status)s."
msgstr ""

#: cinder/volume/drivers/prophetstor/dplcommon.py:109
#, python-format
msgid "Connect to Flexvisor error: %s."
msgstr ""

#: cinder/volume/drivers/prophetstor/dplcommon.py:113
#, python-format
msgid "Connect to Flexvisor failed: %s."
msgstr ""

#: cinder/volume/drivers/prophetstor/dplcommon.py:137
#, python-format
msgid "Failed to send request: %s."
msgstr ""

#: cinder/volume/drivers/prophetstor/dplcommon.py:146
msgid "The Flexvisor service is unavailable."
msgstr ""

#: cinder/volume/drivers/prophetstor/dplcommon.py:160
#, python-format
msgid "Failed to get response: %s."
msgstr ""

#: cinder/volume/drivers/prophetstor/dplcommon.py:169
#, python-format
msgid ""
"%(method)s %(url)s unexpected response status: %(response)s (expects: "
"%(expects)s)."
msgstr ""

#: cinder/volume/drivers/prophetstor/dplcommon.py:187
#: cinder/volume/drivers/prophetstor/dplcommon.py:201
#, python-format
msgid "Call to json.loads() raised an exception: %s."
msgstr ""

#: cinder/volume/drivers/prophetstor/dplcommon.py:191
#: cinder/volume/drivers/prophetstor/dplcommon.py:205
#, python-format
msgid "Read response raised an exception: %s."
msgstr ""

#: cinder/volume/drivers/prophetstor/dplcommon.py:783
#, python-format
msgid "Flexvisor failed to get event %(volume)s (%(status)s)."
msgstr ""

#: cinder/volume/drivers/prophetstor/dplcommon.py:1403
#, python-format
msgid "Flexvisor failed to get pool list.(Error: %d)"
msgstr ""

#: cinder/volume/drivers/prophetstor/dplcommon.py:1406
#, python-format
msgid "Flexvisor failed to get pool list due to %s."
msgstr ""

#: cinder/volume/drivers/prophetstor/dplcommon.py:1458
#, python-format
msgid "Failed to get server info due to %(state)s."
msgstr ""

#: cinder/volume/drivers/prophetstor/dplcommon.py:1487
#, python-format
msgid "Flexvisor failed to get pool %(id)s info."
msgstr ""

#: cinder/volume/drivers/violin/v7000_common.py:176
#, python-format
msgid "Lun create for %s failed!"
msgstr ""

#: cinder/volume/drivers/violin/v7000_common.py:200
#, python-format
msgid "Lun %s has dependent snapshots, skipping lun deletion."
msgstr ""

#: cinder/volume/drivers/violin/v7000_common.py:205
#, python-format
msgid "Lun delete for %s failed!"
msgstr ""

#: cinder/volume/drivers/violin/v7000_common.py:242
msgid "LUN extend failed!"
msgstr ""

#: cinder/volume/drivers/violin/v7000_common.py:285
#, python-format
msgid "Lun create snapshot for volume %(vol)s snapshot %(snap)s failed!"
msgstr ""

#: cinder/volume/drivers/violin/v7000_common.py:318
#, python-format
msgid "Lun delete snapshot for volume %(vol)s snapshot %(snap)s failed!"
msgstr ""

#: cinder/volume/drivers/violin/v7000_common.py:359
#, python-format
msgid "Copy snapshot to volume for snapshot %(snap)s volume %(vol)s failed!"
msgstr ""

#: cinder/volume/drivers/violin/v7000_common.py:402
#, python-format
msgid "Create new lun from lun for source %(src)s => destination %(dest)s failed!"
msgstr ""

#: cinder/volume/drivers/violin/v7000_fcp.py:220
#: cinder/volume/drivers/violin/v7000_fcp.py:249
msgid "Backend returned err for lun export."
msgstr ""

#: cinder/volume/drivers/violin/v7000_fcp.py:253
msgid "LUN unexport failed!"
msgstr ""

#: cinder/volume/drivers/vmware/datastore.py:70
#, python-format
msgid "Storage profile: %s cannot be found in vCenter."
msgstr ""

#: cinder/volume/drivers/vmware/datastore.py:222
msgid "Error occurred while selecting datastore."
msgstr ""

#: cinder/volume/drivers/vmware/vmdk.py:459
#, python-format
msgid "There are no valid hosts available in configured cluster(s): %s."
msgstr ""

#: cinder/volume/drivers/vmware/vmdk.py:465
#, python-format
msgid "There is no valid datastore satisfying requirements: %s."
msgstr ""

#: cinder/volume/drivers/vmware/vmdk.py:721
#, python-format
msgid "Error occurred while copying %(src)s to %(dst)s."
msgstr ""

#: cinder/volume/drivers/vmware/vmdk.py:829
#, python-format
msgid "Error occurred while copying image: %(image_id)s to %(path)s."
msgstr ""

#: cinder/volume/drivers/vmware/vmdk.py:961
#, python-format
msgid "Error occurred while creating volume: %(id)s from image: %(image_id)s."
msgstr ""

#: cinder/volume/drivers/vmware/vmdk.py:1036
#: cinder/volume/drivers/vmware/vmdk.py:1113
#, python-format
msgid "Error occurred while copying image: %(id)s to volume: %(vol)s."
msgstr ""

#: cinder/volume/drivers/vmware/vmdk.py:1324
#, python-format
msgid "Error occurred while cloning backing: %s during retype."
msgstr ""

#: cinder/volume/drivers/vmware/vmdk.py:1409
#, python-format
msgid "Failed to extend volume: %(vol)s to size: %(size)s GB."
msgstr ""

#: cinder/volume/drivers/vmware/vmdk.py:1528
msgid "Error occurred while creating temporary backing."
msgstr ""

#: cinder/volume/drivers/vmware/vmdk.py:1778
#, python-format
msgid "Version string '%s' is not parseable"
msgstr ""

#: cinder/volume/drivers/vmware/vmdk.py:1802
#, python-format
msgid "Not able to configure PBM for vCenter server: %s"
msgstr ""

#: cinder/volume/drivers/vmware/volumeops.py:1400
#, python-format
msgid "Virtual disk device of backing: %s not found."
msgstr ""

#: cinder/volume/drivers/vmware/volumeops.py:1600
#, python-format
msgid "Compute cluster: %s not found."
msgstr ""

#: cinder/volume/drivers/zfssa/restclient.py:298
#, python-format
msgid "REST Not Available: %s"
msgstr ""

#: cinder/volume/drivers/zfssa/restclient.py:304
#, python-format
msgid "Server Busy retry request: %s"
msgstr ""

#: cinder/volume/drivers/zfssa/restclient.py:310
#, python-format
msgid "Authorizing request: %(zfssaurl)s retry: %(retry)d ."
msgstr ""

#: cinder/volume/drivers/zfssa/restclient.py:325
#, python-format
msgid "URLError: %s"
msgstr ""

#: cinder/volume/drivers/zfssa/webdavclient.py:112
#, python-format
msgid "WebDAV returned with %(code)s error during %(method)s call."
msgstr ""

#: cinder/volume/drivers/zfssa/webdavclient.py:117
#, python-format
msgid ""
"WebDAV operation failed with error code: %(code)s reason: %(reason)s "
"Retry attempt %(retry)s in progress."
msgstr ""

#: cinder/volume/drivers/zfssa/zfssaiscsi.py:194
msgid "zfssa_initiator cannot be empty when creating a zfssa_initiator_group."
msgstr ""

#: cinder/volume/drivers/zfssa/zfssaiscsi.py:329
#, python-format
msgid ""
"Volume ID %s was not found on the zfssa device while attempting "
"delete_volume operation."
msgstr ""

#: cinder/volume/drivers/zfssa/zfssaiscsi.py:380
#, python-format
msgid "Snapshot %s: has clones"
msgstr ""

#: cinder/volume/drivers/zfssa/zfssaiscsi.py:492
#, python-format
msgid "Clone Volume:%(volume)s failed from source volume:%(src_vref)s"
msgstr ""

#: cinder/volume/drivers/zfssa/zfssaiscsi.py:539
#: cinder/volume/drivers/zfssa/zfssanfs.py:341
#, python-format
msgid "Image size %(img_size)dGB is larger than volume size %(vol_size)dGB."
msgstr ""

#: cinder/volume/drivers/zfssa/zfssaiscsi.py:566
#: cinder/volume/drivers/zfssa/zfssanfs.py:373
#, python-format
msgid "Cannot clone image %(image)s to volume %(volume)s. Error: %(error)s."
msgstr ""

#: cinder/volume/drivers/zfssa/zfssaiscsi.py:851
#: cinder/volume/drivers/zfssa/zfssanfs.py:612
#, python-format
msgid ""
"Location info needed for backend enabled volume migration not in correct "
"format: %s. Continuing with generic volume migration."
msgstr ""

#: cinder/volume/drivers/zfssa/zfssaiscsi.py:857
msgid ""
"zfssa_replication_ip not set in cinder.conf. zfssa_replication_ip is "
"needed for backend enabled volume migration. Continuing with generic "
"volume migration."
msgstr ""

#: cinder/volume/drivers/zfssa/zfssaiscsi.py:1038
#: cinder/volume/drivers/zfssa/zfssanfs.py:669
#, python-format
msgid "Failed to rename volume %(existing)s to %(new)s. Volume manage failed."
msgstr ""

#: cinder/volume/drivers/zfssa/zfssaiscsi.py:1066
#: cinder/volume/drivers/zfssa/zfssanfs.py:742
#, python-format
msgid "Failed to rename volume %(existing)s to %(new)s. Volume unmanage failed."
msgstr ""

#: cinder/volume/drivers/zfssa/zfssanfs.py:190
#, python-format
msgid "Exception during mounting %s."
msgstr ""

#: cinder/volume/drivers/zfssa/zfssanfs.py:260
#, python-format
msgid ""
"Error in extending volume size: Volume: %(volume)s Vol_Size: %(vol_size)d"
" with Snapshot: %(snapshot)s Snap_Size: %(snap_size)d"
msgstr ""

#: cinder/volume/drivers/zfssa/zfssanfs.py:680
#, python-format
msgid "Failed to set properties for volume %(existing)s. Volume manage failed."
msgstr ""

#: cinder/volume/drivers/zfssa/zfssanfs.py:752
#, python-format
msgid "Failed to set properties for volume %(existing)s. Volume unmanage failed."
msgstr ""

#: cinder/volume/drivers/zfssa/zfssarest.py:775
#, python-format
msgid ""
"Error Getting Snapshot: %(snapshot)s of Volume: %(lun)s in Pool: "
"%(pool)s, Project: %(project)s  Return code: %(ret.status)d, Message: "
"%(ret.data)s."
msgstr ""

#: cinder/volume/drivers/zfssa/zfssarest.py:811
#, python-format
msgid ""
"Error Setting Volume: %(lun)s to InitiatorGroup: %(initiatorgroup)s Pool:"
" %(pool)s Project: %(project)s  Return code: %(ret.status)d Message: "
"%(ret.data)s."
msgstr ""

#: cinder/volume/drivers/zfssa/zfssarest.py:1268
#, python-format
msgid "Cannot delete file %s."
msgstr ""

#: cinder/volume/flows/common.py:61
#, python-format
msgid ""
"Failed setting source volume %(source_volid)s back to its initial "
"%(source_status)s status"
msgstr ""

#: cinder/volume/flows/common.py:96
#, python-format
msgid "Failed updating %(object_type)s %(object_id)s with %(update)s"
msgstr ""

#: cinder/volume/flows/api/create_volume.py:563
#, python-format
msgid "Failed destroying volume entry %s"
msgstr ""

#: cinder/volume/flows/api/create_volume.py:668
#, python-format
msgid "Failed rolling back quota for %s reservations"
msgstr ""

#: cinder/volume/flows/api/create_volume.py:715
#, python-format
msgid "Failed to update quota for deleting volume: %s"
msgstr ""

#: cinder/volume/flows/api/create_volume.py:823
#: cinder/volume/flows/manager/create_volume.py:168
#: cinder/volume/flows/manager/create_volume.py:176
#: cinder/volume/flows/manager/create_volume.py:220
#, python-format
msgid "Volume %s: create failed"
msgstr ""

#: cinder/volume/flows/api/create_volume.py:827
#: cinder/volume/flows/api/manage_existing.py:131
msgid "Unexpected build error:"
msgstr ""

#: cinder/volume/flows/api/manage_existing.py:95
#, python-format
msgid "Failed destroying volume entry: %s."
msgstr ""

#: cinder/volume/flows/api/manage_existing.py:127
#, python-format
msgid "Volume %s: manage failed."
msgstr ""

#: cinder/volume/flows/manager/create_volume.py:120
#, python-format
msgid "Volume %s: update volume state failed."
msgstr ""

#: cinder/volume/flows/manager/create_volume.py:189
#, python-format
msgid "Volume %s: rescheduling failed"
msgstr ""

#: cinder/volume/flows/manager/create_volume.py:349
#, python-format
msgid ""
"Failed notifying about the volume action %(event)s for volume "
"%(volume_id)s"
msgstr ""

#: cinder/volume/flows/manager/create_volume.py:454
#, python-format
msgid ""
"Failed fetching snapshot %(snapshot_id)s bootable flag using the provided"
" glance snapshot %(snapshot_ref_id)s volume reference"
msgstr ""

#: cinder/volume/flows/manager/create_volume.py:471
#, python-format
msgid "Failed updating volume %(volume_id)s bootable flag to true"
msgstr ""

#: cinder/volume/flows/manager/create_volume.py:526
#: cinder/volume/flows/manager/create_volume.py:535
#, python-format
msgid "Failed to copy image %(image_id)s to volume: %(volume_id)s"
msgstr ""

#: cinder/volume/flows/manager/create_volume.py:531
#, python-format
msgid "Failed to copy image to volume: %(volume_id)s"
msgstr ""

#: cinder/volume/flows/manager/create_volume.py:633
#, python-format
msgid "Failed to clone image volume %(id)s."
msgstr ""

#: cinder/volume/flows/manager/create_volume.py:651
#, python-format
msgid "Failed updating volume %(volume_id)s with %(updates)s"
msgstr ""

#: cinder/volume/flows/manager/create_volume.py:808
#, python-format
msgid "Unable to create volume. Volume driver %s not initialized"
msgstr ""

#: cinder/volume/flows/manager/create_volume.py:846
#: cinder/volume/flows/manager/manage_existing.py:85
#, python-format
msgid ""
"Failed updating model of volume %(volume_id)s with creation provided "
"model %(model)s"
msgstr ""

#: cinder/volume/flows/manager/create_volume.py:889
#, python-format
msgid "Failed updating volume %(volume_id)s with %(update)s"
msgstr ""

#: cinder/volume/flows/manager/manage_existing.py:46
#, python-format
msgid "Unable to manage existing volume. Volume driver %s not initialized."
msgstr ""

#: cinder/volume/flows/manager/manage_existing_snapshot.py:64
#, python-format
msgid "Snapshot %s: create failed"
msgstr ""

#: cinder/volume/flows/manager/manage_existing_snapshot.py:90
#, python-format
msgid ""
"Failed notifying about the snapshot action %(event)s for snapshot "
"%(snp_id)s."
msgstr ""

#: cinder/volume/flows/manager/manage_existing_snapshot.py:111
#, python-format
msgid "Unable to manage existing snapshot. Volume driver %s not initialized."
msgstr ""

#: cinder/volume/flows/manager/manage_existing_snapshot.py:180
#, python-format
msgid "Failed rolling back quota for %s reservations."
msgstr ""

#: cinder/volume/flows/manager/manage_existing_snapshot.py:224
#, python-format
msgid "Failed to update quota while deleting snapshots: %s"
msgstr ""

#: cinder/volume/flows/manager/manage_existing_snapshot.py:251
#, python-format
msgid ""
"Failed updating model of snapshot %(snapshot_id)s with creation provided "
"model %(model)s."
msgstr ""

#: cinder/volume/flows/manager/manage_existing_snapshot.py:297
#, python-format
msgid "Failed updating snapshot %(snapshot_id)s with %(update)s."
msgstr ""

#: cinder/volume/targets/cxt.py:156 cinder/volume/targets/scst.py:132
#, python-format
msgid "Failed to create iscsi target for volume id:%(vol_id)s: %(e)s"
msgstr ""

#: cinder/volume/targets/cxt.py:177
#, python-format
msgid ""
"Failed to create iscsi target for volume id:%(vol_id)s. Please verify "
"your configuration in %(volumes_dir)s'"
msgstr ""

#: cinder/volume/targets/cxt.py:239 cinder/volume/targets/scst.py:337
#: cinder/volume/targets/scst.py:356
#, python-format
msgid "Failed to remove iscsi target for volume id:%(vol_id)s: %(e)s"
msgstr ""

#: cinder/volume/targets/iet.py:54
#, python-format
msgid "Failed to open iet session list for %s"
msgstr ""

#: cinder/volume/targets/iet.py:104
#, python-format
msgid "Failed to create iscsi target for volume id:%s"
msgstr ""

#: cinder/volume/targets/iet.py:126
#, python-format
msgid "Failed to create %(conf)s for volume id:%(vol_id)s"
msgstr ""

#: cinder/volume/targets/iet.py:142
#, python-format
msgid "Failed to update %(conf)s for volume id:%(vol_id)s"
msgstr ""

#: cinder/volume/targets/iet.py:159
#, python-format
msgid "Failed to remove iscsi target for volume id:%s"
msgstr ""

#: cinder/volume/targets/iet.py:186
#, python-format
msgid ""
"Failed to update %(conf)s for volume id %(vol_id)s after removing iscsi "
"target"
msgstr ""

#: cinder/volume/targets/iscsi.py:301
msgid "The volume driver requires the iSCSI initiator name in the connector."
msgstr ""

#: cinder/volume/targets/lio.py:41
msgid "cinder-rtstool is not installed correctly"
msgstr ""

#: cinder/volume/targets/lio.py:129 cinder/volume/targets/lio.py:137
#, python-format
msgid "Failed to create iscsi target for volume id:%s."
msgstr ""

#: cinder/volume/targets/lio.py:157
#, python-format
msgid "Failed to remove iscsi target for volume id:%s."
msgstr ""

#: cinder/volume/targets/lio.py:179
#, python-format
msgid "Failed to add initiator iqn %s to target"
msgstr ""

#: cinder/volume/targets/lio.py:200
#, python-format
msgid "Failed to delete initiator iqn %s from target."
msgstr ""

#: cinder/volume/targets/scst.py:121
#, python-format
msgid "Failed to set attribute for enable target driver %s"
msgstr ""

#: cinder/volume/targets/scst.py:140
#, python-format
msgid "Failed to set 'enable' attribute for SCST target %s"
msgstr ""

#: cinder/volume/targets/scst.py:172
#, python-format
msgid "Failed to create group to SCST target %s"
msgstr ""

#: cinder/volume/targets/scst.py:184
#, python-format
msgid "Failed to add initiator to group  for SCST target %s"
msgstr ""

#: cinder/volume/targets/scst.py:201
#, python-format
msgid "Failed to add device to handler %s"
msgstr ""

#: cinder/volume/targets/scst.py:218
#, python-format
msgid "Failed to add lun to SCST target id:%(vol_id)s: %(e)s"
msgstr ""

#: cinder/volume/targets/scst.py:229
msgid "Failed to write in /etc/scst.conf."
msgstr ""

#: cinder/volume/targets/scst.py:314
#, python-format
msgid ""
"Skipping remove_export. No iscsi_target ispresently exported for volume: "
"%s"
msgstr ""

#: cinder/volume/targets/scst.py:345 cinder/volume/targets/scst.py:380
#, python-format
msgid "Failed to close disk device %s"
msgstr ""

#: cinder/volume/targets/scst.py:371
#, python-format
msgid "Failed to remove LUN %s"
msgstr ""

#: cinder/volume/targets/tgt.py:101
#, python-format
msgid ""
"Failed recovery attempt to create iscsi backing lun for Volume "
"ID:%(vol_id)s: %(e)s"
msgstr ""

#: cinder/volume/targets/tgt.py:197
#, python-format
msgid "Failed to create iscsi target for Volume ID: %(vol_id)s: %(e)s"
msgstr ""

#: cinder/volume/targets/tgt.py:221
#, python-format
msgid ""
"Failed to create iscsi target for Volume ID: %(vol_id)s. Please ensure "
"your tgtd config file contains 'include %(volumes_dir)s/*'"
msgstr ""

#: cinder/volume/targets/tgt.py:280 cinder/volume/targets/tgt.py:303
#, python-format
msgid "Failed to remove iscsi target for Volume ID: %(vol_id)s: %(e)s"
msgstr ""

#: cinder/zonemanager/fc_san_lookup_service.py:91
msgid "Unable to get device mapping from network."
msgstr ""

#: cinder/zonemanager/drivers/brocade/brcd_fc_san_lookup_service.py:129
#, python-format
msgid "Failed collecting name server info from fabric %s"
msgstr ""

#: cinder/zonemanager/drivers/brocade/brcd_fc_san_lookup_service.py:190
msgid "Failed collecting nsshow info for fabric"
msgstr ""

#: cinder/zonemanager/drivers/brocade/brcd_fc_san_lookup_service.py:199
msgid "Failed collecting nscamshow"
msgstr ""

#: cinder/zonemanager/drivers/brocade/brcd_fc_zone_client_cli.py:84
#: cinder/zonemanager/drivers/cisco/cisco_fc_zone_client_cli.py:90
#, python-format
msgid "Failed getting active zone set from fabric %s"
msgstr ""

#: cinder/zonemanager/drivers/brocade/brcd_fc_zone_client_cli.py:155
#: cinder/zonemanager/drivers/cisco/cisco_fc_zone_client_cli.py:176
#, python-format
msgid "Deleting zone failed %s"
msgstr ""

#: cinder/zonemanager/drivers/brocade/brcd_fc_zone_client_cli.py:269
#, python-format
msgid "Failed collecting nsshow info for fabric %s"
msgstr ""

#: cinder/zonemanager/drivers/brocade/brcd_fc_zone_client_cli.py:341
msgid "No CLI output for firmware version check"
msgstr ""

#: cinder/zonemanager/drivers/brocade/brcd_fc_zone_client_cli.py:410
#: cinder/zonemanager/drivers/brocade/brcd_fc_zone_client_cli.py:473
#: cinder/zonemanager/drivers/cisco/cisco_fc_zone_client_cli.py:431
msgid "Error executing SSH command."
msgstr ""

#: cinder/zonemanager/drivers/brocade/brcd_fc_zone_client_cli.py:492
#, python-format
msgid "Error executing command via ssh: %s"
msgstr ""

#: cinder/zonemanager/drivers/brocade/brcd_fc_zone_client_cli.py:551
msgid "Error closing channel."
msgstr ""

#: cinder/zonemanager/drivers/brocade/brcd_fc_zone_driver.py:393
#: cinder/zonemanager/drivers/brocade/brcd_fc_zone_driver.py:433
msgid "Error getting name server info."
msgstr ""

#: cinder/zonemanager/drivers/cisco/cisco_fc_san_lookup_service.py:184
msgid "Failed collecting show fcns database for fabric"
msgstr ""

#: cinder/zonemanager/drivers/cisco/cisco_fc_zone_client_cli.py:225
#, python-format
msgid "Failed getting zone status from fabric %s"
msgstr ""

#: cinder/zonemanager/drivers/cisco/cisco_fc_zone_client_cli.py:306
#, python-format
msgid "Failed collecting fcns database info for fabric %s"
msgstr ""

#: cinder/zonemanager/drivers/cisco/cisco_fc_zone_client_cli.py:449
msgid "Error executing command via ssh."
msgstr ""

#: cinder/zonemanager/drivers/cisco/cisco_fc_zone_driver.py:454
msgid "Error getting show fcns database info."
msgstr ""

